Workbook
Name ABRIL: #REF!
Name ACACFTLOCK: #REF!
Name ACCCAACFTLOCK: #REF!
Name ACLLOCKONLYACFTLOCK: #REF!
Name agosto: #REF!
Name CCLLOCKONLYACFTLOCK: #REF!
Name COCACFTLOCK: #REF!
Name COCCCAACFTLOCK: #REF!
Name diciembre: #REF!
Name ENERO: #REF!
Name epfeb: #REF!
Name epjan: #REF!
Name febrero: #REF!
Name GAT_DAY: #REF!
Name GAT_ELEV: #REF!
Name GAT_ESA_ACFT: #REF!
Name GAT_ESA_AREA: #REF!
Name GAT_ESA_ELEV: #REF!
Name GAT_EVAP_AVG: #REF!
Name GAT_MONTH: #REF!
Name GATACFTLOCK: #REF!
Name Jan: #REF!
Name Julio: #REF!
Name JUNIO: #REF!
Name MAD_ESA_ACFT: #REF!
Name MAD_ESA_AREA: #REF!
Name MAD_ESA_ELEV: #REF!
Name MAD_EVAP_AVG: #REF!
Name MAD_SED_EA: #REF!
Name MAD_SED_ES: #REF!
Name Marzo: #REF!
Name MAYO: #REF!
Name MONTH_POR: #REF!
Name noviembre: #REF!
Name octubre: #REF!
Name PMACFTLOCK: #REF!
Name ROUNDED_ELEV: #REF!
Name septiembre: #REF!
Name YEAR_POR: #REF!

Sheet Resumen 1  
B2: Descripción: | C2: ALHA: P95 -10% GAT: P95 -40% Hidrogeneración: Variable según aporte.
B6: Título: | C6: Modelo GLR
B7: Escenario: | C7: =+[1]Balance_Madden!F2 -> GLR ESC1 P95 Ultimo Decenio -10#ALHA/ -40$GAT (Transitos36)
B8: Autor: | C8: =+[1]GLR!B13 -> JFRodriguez
C10: Niveles | E10: Aportes | G10: Hidrogeneración | I10: Vertido | K10: Esclusajes | P10: Evaporación | R10: Salidas Netas
C11: Alhajuela | D11: Gatún | E11: Alhajuela | F11: Gatún | G11: Alhajuela | H11: Gatún | I11: Alhajuela | J11: Gatún | K11: Gatún | P11: Alhajuela | Q11: Gatún | R11: Alhajuela | S11: =+K11 -> Gatún
B12: Fecha Hora | C12: (pies) | D12: (pies) | E12: (m3/s) | F12: (m3/s) | G12: (MW) | H12: (MW) | I12: (m3/s) | J12: (m3/s) | O12: (hm^3) | P12: (m3/s) | Q12: (m3/s) | R12: (m3/s) | S12: (m3/s)
B13: Fecha Hora | C13: Elev_Alha(pies) | D13: Elev_Gatún(pies) | E13: AT_Alha(m^3/s) | F13: AT_Gatún(m^3/s) | G13: Hidro_Alha(MW) | H13: Hidro_Gatún(MW) | I13: Vert_Alha(m^3/s) | J13: Vert_Gatún(m^3/s) | K13: Cant. PMX | L13: Ahorro PMX | M13: Cant.NPX | N13: Ahorro NPX | O13: Vol_Tránsito(hm^3) | P13: Evap_Alha(m^3/s) | Q13: Evap_Gatún(m^3/s) | R13: SN_Alha (m^3/s) | S13: SN_GAT(m^3/s) | T13: Gat 97 | U13: Alha97 | V13: Calado NPX (pies) | W13: Cambio calado (día exacto) | X13: Primer_día_del_cambio | Y13: No_cambio | Z13: Fecha_cambio_limpia | AA13: Calado_cambio_limpio | AB13: Calado vigente | AC13: Días desde cambio | AD13: Nivel 80 | AF13: Fecha del cambio | AG13: Calado NPX (pies) | AH13: Días hasta próximo cambio | AI13: Nota
A14: =+INT(B14) -> 46204 | B14: =+[1]Balance_Madden!A12 -> 46204 | C14: =+VLOOKUP(B14,[1]Balance_Madden!$A$12:$E$5000,2) -> 226.68 | D14: =+VLOOKUP(B14,[1]Balance_Gatún!$A$13:$E$5087,2) -> 84.932 | E14: =+VLOOKUP(B14,[1]Balance_Madden!$A$12:$E$5087,5)/35.32 -> 67.324604 | F14: =+VLOOKUP(B14,[1]Balance_Gatún!$A$13:$E$5087,5)/35.32 -> 56.059711 | G14: =+VLOOKUP(B14,[1]Balance_Madden!$A$12:$K$5087,9)/111 -> 18.09009 | H14: =+VLOOKUP(B14,[1]Balance_Gatún!$A$13:$U$5087,21)/186 -> 0 | I14: =+(VLOOKUP(B14,[1]Balance_Madden!$A$12:$K$5087,10)/35.32)+VLOOKUP(B14,[1]Balance_Madden!$A$12:$K$5087,11)/35.32 -> 0 | J14: =+VLOOKUP(B14,[1]Balance_Gatún!$A$13:$AD$5087,23)/35.32+ VLOOKUP(B14,[1]Balance_Gatún!$A$13:$AD$5087,17)/35.32 -> 0 | K14: =+VLOOKUP(B14,[1]Balance_Gatún!$A$13:$AC$5087,10) -> 26 | L14: =+VLOOKUP(B14,[1]Balance_Gatún!$A$13:$AC$5087,11) -> XFILL_PMG50% | M14: =+VLOOKUP(B14,[1]Balance_Gatún!$A$13:$AC$5087,12) -> 10 | N14: =+VLOOKUP(B14,[1]Balance_Gatún!$A$13:$AC$5087,13) -> TA | O14: =+VLOOKUP(B14,[1]Balance_Gatún!$A$13:$AC$5087,14)/408.7 -> 8.1799679 | P14: =+VLOOKUP(B14,[1]Balance_Madden!$A$12:$V$5087,12)/35.32 -> 1.8610349 | Q14: =+VLOOKUP(B14,[1]Balance_Gatún!$A$13:$AD$5087,15)/35.32 -> 20.434026 | R14: =+VLOOKUP(B14,[1]Balance_Madden!$A$12:$V$5087,14)/35.32 -> 70.966358 | S14: =[1]Balance_Gatún!X13/35.32 -> 126.69989 | T14: 55.357049 | U14: 74.671936 | V14: =LOOKUP(D14,[1]Parámetros!$A$7:$A$24,[1]Parámetros!$B$7:$B$24) -> 49.5 | W14: =IF(V14<>V13,"Cambio Calado","") -> Cambio Calado | X14: =IF(W14<>"",INT(A14),"") -> 46204 | Y14: =IF($W14="Cambio Calado",COUNTIF($W14:W$14,"Cambio Calado"),"") -> 1 | Z14: =IF($W14="Cambio Calado",$X14,"") -> 46204 | AA14: =IF($W14="Cambio Calado",$V14,"") -> 49.5 | AB14: =IFERROR(LOOKUP($A14,$Z14:$Z$14,$AA14:$AA$14),$U14) -> 49.5 | AC14: =IFERROR($A15-LOOKUP($A15,$Z$14:$Z14),"") -> 1 | AD14: {=IF(B14<>"",80,_xludf.NA())} -> 80 | AF14: =IFERROR(INDEX($X$14:$X$197,MATCH(ROWS($AF14:AF$14),$Y$14:$Y$197,0)),"") -> 46204 | AG14: =IFERROR(INDEX($V$14:$V$197,MATCH(ROWS($AF14:AF$14),$Y$14:$Y$197,0)),"") -> 49.5 | AH14: =IFERROR(INDEX($X$14:$X$197,MATCH(ROWS($AF14:AF$14)+1,$Y$14:$Y$197,0))-AF14,"") -> 37 | AI14: =IF(AF14="","","Cambio Calado") -> Cambio Calado
A15: =+INT(B15) -> 46205 | B15: =+[1]Balance_Madden!A13 -> 46205 | C15: =+VLOOKUP(B15,[1]Balance_Madden!$A$12:$E$5000,2) -> 226.32 | D15: =+VLOOKUP(B15,[1]Balance_Gatún!$A$13:$E$5087,2) -> 84.912 | E15: =+VLOOKUP(B15,[1]Balance_Madden!$A$12:$E$5087,5)/35.32 -> 30.045017 | F15: =+VLOOKUP(B15,[1]Balance_Gatún!$A$13:$E$5087,5)/35.32 -> 49.616789 | G15: =+VLOOKUP(B15,[1]Balance_Madden!$A$12:$K$5087,9)/111 -> 18.09009 | H15: =+VLOOKUP(B15,[1]Balance_Gatún!$A$13:$U$5087,21)/186 -> 0 | I15: =+(VLOOKUP(B15,[1]Balance_Madden!$A$12:$K$5087,10)/35.32)+VLOOKUP(B15,[1]Balance_Madden!$A$12:$K$5087,11)/35.32 -> 0 | J15: =+VLOOKUP(B15,[1]Balance_Gatún!$A$13:$AD$5087,23)/35.32+ VLOOKUP(B15,[1]Balance_Gatún!$A$13:$AD$5087,17)/35.32 -> 0 | K15: =+VLOOKUP(B15,[1]Balance_Gatún!$A$13:$AC$5087,10) -> 26 | L15: =+VLOOKUP(B15,[1]Balance_Gatún!$A$13:$AC$5087,11) -> XFILL_PMG50% | M15: =+VLOOKUP(B15,[1]Balance_Gatún!$A$13:$AC$5087,12) -> 10 | N15: =+VLOOKUP(B15,[1]Balance_Gatún!$A$13:$AC$5087,13) -> TA+CCL50% | O15: =+VLOOKUP(B15,[1]Balance_Gatún!$A$13:$AC$5087,14)/408.7 -> 7.5832144 | P15: =+VLOOKUP(B15,[1]Balance_Madden!$A$12:$V$5087,12)/35.32 -> 1.8390793 | Q15: =+VLOOKUP(B15,[1]Balance_Gatún!$A$13:$AD$5087,15)/35.32 -> 20.293115 | R15: =+VLOOKUP(B15,[1]Balance_Madden!$A$12:$V$5087,14)/35.32 -> 70.944402 | S15: =[1]Balance_Gatún!X14/35.32 -> 119.65374 | T15: 39.534935 | U15: 61.499788 | V15: =LOOKUP(D15,[1]Parámetros!$A$7:$A$24,[1]Parámetros!$B$7:$B$24) -> 49.5 | W15: =IF(V15<>V14,"Cambio Calado","") | X15: =IF(W15<>"",INT(A15),"") | Y15: =IF($W15="Cambio Calado",COUNTIF($W$14:W15,"Cambio Calado"),"") | Z15: =IF($W15="Cambio Calado",$X15,"") | AA15: =IF($W15="Cambio Calado",$V15,"") | AB15: =IFERROR(LOOKUP($A15,$Z$14:$Z15,$AA$14:$AA15),$U15) -> 49.5 | AC15: =IFERROR($A16-LOOKUP($A16,$Z$14:$Z15),"") -> 2 | AD15: {=IF(B15<>"",80,_xludf.NA())} -> 80 | AF15: =IFERROR(INDEX($X$14:$X$197,MATCH(ROWS($AF$14:AF15),$Y$14:$Y$197,0)),"") -> 46241 | AG15: =IFERROR(INDEX($V$14:$V$197,MATCH(ROWS($AF$14:AF15),$Y$14:$Y$197,0)),"") -> 49 | AH15: =IFERROR(INDEX($X$14:$X$197,MATCH(ROWS($AF$14:AF15)+1,$Y$14:$Y$197,0))-AF15,"") -> 14 | AI15: =IF(AF15="","","Cambio Calado") -> Cambio Calado
A16: =+INT(B16) -> 46206 | B16: =+[1]Balance_Madden!A14 -> 46206 | C16: =+VLOOKUP(B16,[1]Balance_Madden!$A$12:$E$5000,2) -> 226.04 | D16: =+VLOOKUP(B16,[1]Balance_Gatún!$A$13:$E$5087,2) -> 84.883 | E16: =+VLOOKUP(B16,[1]Balance_Madden!$A$12:$E$5087,5)/35.32 -> 25.002378 | F16: =+VLOOKUP(B16,[1]Balance_Gatún!$A$13:$E$5087,5)/35.32 -> 42.174094 | G16: =+VLOOKUP(B16,[1]Balance_Madden!$A$12:$K$5087,9)/111 -> 18.09009 | H16: =+VLOOKUP(B16,[1]Balance_Gatún!$A$13:$U$5087,21)/186 -> 0 | I16: =+(VLOOKUP(B16,[1]Balance_Madden!$A$12:$K$5087,10)/35.32)+VLOOKUP(B16,[1]Balance_Madden!$A$12:$K$5087,11)/35.32 -> 0 | J16: =+VLOOKUP(B16,[1]Balance_Gatún!$A$13:$AD$5087,23)/35.32+ VLOOKUP(B16,[1]Balance_Gatún!$A$13:$AD$5087,17)/35.32 -> 0 | K16: =+VLOOKUP(B16,[1]Balance_Gatún!$A$13:$AC$5087,10) -> 26 | L16: =+VLOOKUP(B16,[1]Balance_Gatún!$A$13:$AC$5087,11) -> XFILL_PMG50% | M16: =+VLOOKUP(B16,[1]Balance_Gatún!$A$13:$AC$5087,12) -> 10 | N16: =+VLOOKUP(B16,[1]Balance_Gatún!$A$13:$AC$5087,13) -> TA+CCL50% | O16: =+VLOOKUP(B16,[1]Balance_Gatún!$A$13:$AC$5087,14)/408.7 -> 7.5766986 | P16: =+VLOOKUP(B16,[1]Balance_Madden!$A$12:$V$5087,12)/35.32 -> 1.7792116 | Q16: =+VLOOKUP(B16,[1]Balance_Gatún!$A$13:$AD$5087,15)/35.32 -> 19.705062 | R16: =+VLOOKUP(B16,[1]Balance_Madden!$A$12:$V$5087,14)/35.32 -> 70.884534 | S16: =[1]Balance_Gatún!X15/35.32 -> 118.99029 | T16: 47.509304 | U16: 54.962463 | V16: =LOOKUP(D16,[1]Parámetros!$A$7:$A$24,[1]Parámetros!$B$7:$B$24) -> 49.5 | W16: =IF(V16<>V15,"Cambio Calado","") | X16: =IF(W16<>"",INT(A16),"") | Y16: =IF($W16="Cambio Calado",COUNTIF($W$14:W16,"Cambio Calado"),"") | Z16: =IF($W16="Cambio Calado",$X16,"") | AA16: =IF($W16="Cambio Calado",$V16,"") | AB16: =IFERROR(LOOKUP($A16,$Z$14:$Z16,$AA$14:$AA16),$U16) -> 49.5 | AC16: =IFERROR($A17-LOOKUP($A17,$Z$14:$Z16),"") -> 3 | AD16: {=IF(B16<>"",80,_xludf.NA())} -> 80 | AF16: =IFERROR(INDEX($X$14:$X$197,MATCH(ROWS($AF$14:AF16),$Y$14:$Y$197,0)),"") -> 46255 | AG16: =IFERROR(INDEX($V$14:$V$197,MATCH(ROWS($AF$14:AF16),$Y$14:$Y$197,0)),"") -> 48.5 | AH16: =IFERROR(INDEX($X$14:$X$197,MATCH(ROWS($AF$14:AF16)+1,$Y$14:$Y$197,0))-AF16,"") -> 8 | AI16: =IF(AF16="","","Cambio Calado") -> Cambio Calado
A17: =+INT(B17) -> 46207 | B17: =+[1]Balance_Madden!A15 -> 46207 | C17: =+VLOOKUP(B17,[1]Balance_Madden!$A$12:$E$5000,2) -> 225.98 | D17: =+VLOOKUP(B17,[1]Balance_Gatún!$A$13:$E$5087,2) -> 84.903 | E17: =+VLOOKUP(B17,[1]Balance_Madden!$A$12:$E$5087,5)/35.32 -> 54.252407 | F17: =+VLOOKUP(B17,[1]Balance_Gatún!$A$13:$E$5087,5)/35.32 -> 93.555011 | G17: =+VLOOKUP(B17,[1]Balance_Madden!$A$12:$K$5087,9)/111 -> 18.09009 | H17: =+VLOOKUP(B17,[1]Balance_Gatún!$A$13:$U$5087,21)/186 -> 0 | I17: =+(VLOOKUP(B17,[1]Balance_Madden!$A$12:$K$5087,10)/35.32)+VLOOKUP(B17,[1]Balance_Madden!$A$12:$K$5087,11)/35.32 -> 0 | J17: =+VLOOKUP(B17,[1]Balance_Gatún!$A$13:$AD$5087,23)/35.32+ VLOOKUP(B17,[1]Balance_Gatún!$A$13:$AD$5087,17)/35.32 -> 0 | K17: =+VLOOKUP(B17,[1]Balance_Gatún!$A$13:$AC$5087,10) -> 26 | L17: =+VLOOKUP(B17,[1]Balance_Gatún!$A$13:$AC$5087,11) -> XFILL_PMG50% | M17: =+VLOOKUP(B17,[1]Balance_Gatún!$A$13:$AC$5087,12) -> 10 | N17: =+VLOOKUP(B17,[1]Balance_Gatún!$A$13:$AC$5087,13) -> TA+CCL50% | O17: =+VLOOKUP(B17,[1]Balance_Gatún!$A$13:$AC$5087,14)/408.7 -> 7.5811922 | P17: =+VLOOKUP(B17,[1]Balance_Madden!$A$12:$V$5087,12)/35.32 -> 1.2100773 | Q17: =+VLOOKUP(B17,[1]Balance_Gatún!$A$13:$AD$5087,15)/35.32 -> 13.41688 | R17: =+VLOOKUP(B17,[1]Balance_Madden!$A$12:$V$5087,14)/35.32 -> 70.3154 | S17: =[1]Balance_Gatún!X16/35.32 -> 112.7541 | T17: 36.622389 | U17: 51.691882 | V17: =LOOKUP(D17,[1]Parámetros!$A$7:$A$24,[1]Parámetros!$B$7:$B$24) -> 49.5 | W17: =IF(V17<>V16,"Cambio Calado","") | X17: =IF(W17<>"",INT(A17),"") | Y17: =IF($W17="Cambio Calado",COUNTIF($W$14:W17,"Cambio Calado"),"") | Z17: =IF($W17="Cambio Calado",$X17,"") | AA17: =IF($W17="Cambio Calado",$V17,"") | AB17: =IFERROR(LOOKUP($A17,$Z$14:$Z17,$AA$14:$AA17),$U17) -> 49.5 | AC17: =IFERROR($A18-LOOKUP($A18,$Z$14:$Z17),"") -> 4 | AD17: {=IF(B17<>"",80,_xludf.NA())} -> 80 | AF17: =IFERROR(INDEX($X$14:$X$197,MATCH(ROWS($AF$14:AF17),$Y$14:$Y$197,0)),"") -> 46263 | AG17: =IFERROR(INDEX($V$14:$V$197,MATCH(ROWS($AF$14:AF17),$Y$14:$Y$197,0)),"") -> 49 | AH17: =IFERROR(INDEX($X$14:$X$197,MATCH(ROWS($AF$14:AF17)+1,$Y$14:$Y$197,0))-AF17,"") -> 21 | AI17: =IF(AF17="","","Cambio Calado") -> Cambio Calado
A18: =+INT(B18) -> 46208 | B18: =+[1]Balance_Madden!A16 -> 46208 | C18: =+VLOOKUP(B18,[1]Balance_Madden!$A$12:$E$5000,2) -> 225.71 | D18: =+VLOOKUP(B18,[1]Balance_Gatún!$A$13:$E$5087,2) -> 84.87 | E18: =+VLOOKUP(B18,[1]Balance_Madden!$A$12:$E$5087,5)/35.32 -> 45.505946 | F18: =+VLOOKUP(B18,[1]Balance_Gatún!$A$13:$E$5087,5)/35.32 -> 64.212231 | G18: =+VLOOKUP(B18,[1]Balance_Madden!$A$12:$K$5087,9)/111 -> 18.09009 | H18: =+VLOOKUP(B18,[1]Balance_Gatún!$A$13:$U$5087,21)/186 -> 0 | I18: =+(VLOOKUP(B18,[1]Balance_Madden!$A$12:$K$5087,10)/35.32)+VLOOKUP(B18,[1]Balance_Madden!$A$12:$K$5087,11)/35.32 -> 0 | J18: =+VLOOKUP(B18,[1]Balance_Gatún!$A$13:$AD$5087,23)/35.32+ VLOOKUP(B18,[1]Balance_Gatún!$A$13:$AD$5087,17)/35.32 -> 0 | K18: =+VLOOKUP(B18,[1]Balance_Gatún!$A$13:$AC$5087,10) -> 26 | L18: =+VLOOKUP(B18,[1]Balance_Gatún!$A$13:$AC$5087,11) -> XFILL_PMG50% | M18: =+VLOOKUP(B18,[1]Balance_Gatún!$A$13:$AC$5087,12) -> 10 | N18: =+VLOOKUP(B18,[1]Balance_Gatún!$A$13:$AC$5087,13) -> TA+CCL50% | O18: =+VLOOKUP(B18,[1]Balance_Gatún!$A$13:$AC$5087,14)/408.7 -> 7.5737778 | P18: =+VLOOKUP(B18,[1]Balance_Madden!$A$12:$V$5087,12)/35.32 -> 0.60874735 | Q18: =+VLOOKUP(B18,[1]Balance_Gatún!$A$13:$AD$5087,15)/35.32 -> 6.7732522 | R18: =+VLOOKUP(B18,[1]Balance_Madden!$A$12:$V$5087,14)/35.32 -> 69.71407 | S18: =[1]Balance_Gatún!X17/35.32 -> 106.05309 | T18: 26.038929 | U18: 110.65149 | V18: =LOOKUP(D18,[1]Parámetros!$A$7:$A$24,[1]Parámetros!$B$7:$B$24) -> 49.5 | W18: =IF(V18<>V17,"Cambio Calado","") | X18: =IF(W18<>"",INT(A18),"") | Y18: =IF($W18="Cambio Calado",COUNTIF($W$14:W18,"Cambio Calado"),"") | Z18: =IF($W18="Cambio Calado",$X18,"") | AA18: =IF($W18="Cambio Calado",$V18,"") | AB18: =IFERROR(LOOKUP($A18,$Z$14:$Z18,$AA$14:$AA18),$U18) -> 49.5 | AC18: =IFERROR($A19-LOOKUP($A19,$Z$14:$Z18),"") -> 5 | AD18: {=IF(B18<>"",80,_xludf.NA())} -> 80 | AF18: =IFERROR(INDEX($X$14:$X$197,MATCH(ROWS($AF$14:AF18),$Y$14:$Y$197,0)),"") -> 46284 | AG18: =IFERROR(INDEX($V$14:$V$197,MATCH(ROWS($AF$14:AF18),$Y$14:$Y$197,0)),"") -> 49.5 | AH18: =IFERROR(INDEX($X$14:$X$197,MATCH(ROWS($AF$14:AF18)+1,$Y$14:$Y$197,0))-AF18,"") -> 11 | AI18: =IF(AF18="","","Cambio Calado") -> Cambio Calado
A19: =+INT(B19) -> 46209 | B19: =+[1]Balance_Madden!A17 -> 46209 | C19: =+VLOOKUP(B19,[1]Balance_Madden!$A$12:$E$5000,2) -> 225.45 | D19: =+VLOOKUP(B19,[1]Balance_Gatún!$A$13:$E$5087,2) -> 84.869 | E19: =+VLOOKUP(B19,[1]Balance_Madden!$A$12:$E$5087,5)/35.32 -> 39.236495 | F19: =+VLOOKUP(B19,[1]Balance_Gatún!$A$13:$E$5087,5)/35.32 -> 43.602152 | G19: =+VLOOKUP(B19,[1]Balance_Madden!$A$12:$K$5087,9)/111 -> 18.09009 | H19: =+VLOOKUP(B19,[1]Balance_Gatún!$A$13:$U$5087,21)/186 -> 0 | I19: =+(VLOOKUP(B19,[1]Balance_Madden!$A$12:$K$5087,10)/35.32)+VLOOKUP(B19,[1]Balance_Madden!$A$12:$K$5087,11)/35.32 -> 0 | J19: =+VLOOKUP(B19,[1]Balance_Gatún!$A$13:$AD$5087,23)/35.32+ VLOOKUP(B19,[1]Balance_Gatún!$A$13:$AD$5087,17)/35.32 -> 0 | K19: =+VLOOKUP(B19,[1]Balance_Gatún!$A$13:$AC$5087,10) -> 26 | L19: =+VLOOKUP(B19,[1]Balance_Gatún!$A$13:$AC$5087,11) -> XFILL_PMG50% | M19: =+VLOOKUP(B19,[1]Balance_Gatún!$A$13:$AC$5087,12) -> 10 | N19: =+VLOOKUP(B19,[1]Balance_Gatún!$A$13:$AC$5087,13) -> TA+CCL50% | O19: =+VLOOKUP(B19,[1]Balance_Gatún!$A$13:$AC$5087,14)/408.7 -> 7.5735531 | P19: =+VLOOKUP(B19,[1]Balance_Madden!$A$12:$V$5087,12)/35.32 -> 0.21147595 | Q19: =+VLOOKUP(B19,[1]Balance_Gatún!$A$13:$AD$5087,15)/35.32 -> 2.3618905 | R19: =+VLOOKUP(B19,[1]Balance_Madden!$A$12:$V$5087,14)/35.32 -> 69.316799 | S19: =[1]Balance_Gatún!X18/35.32 -> 101.63913 | T19: 14.255201 | U19: 40.842379 | V19: =LOOKUP(D19,[1]Parámetros!$A$7:$A$24,[1]Parámetros!$B$7:$B$24) -> 49.5 | W19: =IF(V19<>V18,"Cambio Calado","") | X19: =IF(W19<>"",INT(A19),"") | Y19: =IF($W19="Cambio Calado",COUNTIF($W$14:W19,"Cambio Calado"),"") | Z19: =IF($W19="Cambio Calado",$X19,"") | AA19: =IF($W19="Cambio Calado",$V19,"") | AB19: =IFERROR(LOOKUP($A19,$Z$14:$Z19,$AA$14:$AA19),$U19) -> 49.5 | AC19: =IFERROR($A20-LOOKUP($A20,$Z$14:$Z19),"") -> 6 | AD19: {=IF(B19<>"",80,_xludf.NA())} -> 80 | AF19: =IFERROR(INDEX($X$14:$X$197,MATCH(ROWS($AF$14:AF19),$Y$14:$Y$197,0)),"") -> 46295 | AG19: =IFERROR(INDEX($V$14:$V$197,MATCH(ROWS($AF$14:AF19),$Y$14:$Y$197,0)),"") -> 50 | AH19: =IFERROR(INDEX($X$14:$X$197,MATCH(ROWS($AF$14:AF19)+1,$Y$14:$Y$197,0))-AF19,"") -> 1 | AI19: =IF(AF19="","","Cambio Calado") -> Cambio Calado
A20: =+INT(B20) -> 46210 | B20: =+[1]Balance_Madden!A18 -> 46210 | C20: =+VLOOKUP(B20,[1]Balance_Madden!$A$12:$E$5000,2) -> 225.14 | D20: =+VLOOKUP(B20,[1]Balance_Gatún!$A$13:$E$5087,2) -> 84.829 | E20: =+VLOOKUP(B20,[1]Balance_Madden!$A$12:$E$5087,5)/35.32 -> 35.276869 | F20: =+VLOOKUP(B20,[1]Balance_Gatún!$A$13:$E$5087,5)/35.32 -> 42.571631 | G20: =+VLOOKUP(B20,[1]Balance_Madden!$A$12:$K$5087,9)/111 -> 18.09009 | H20: =+VLOOKUP(B20,[1]Balance_Gatún!$A$13:$U$5087,21)/186 -> 0 | I20: =+(VLOOKUP(B20,[1]Balance_Madden!$A$12:$K$5087,10)/35.32)+VLOOKUP(B20,[1]Balance_Madden!$A$12:$K$5087,11)/35.32 -> 0 | J20: =+VLOOKUP(B20,[1]Balance_Gatún!$A$13:$AD$5087,23)/35.32+ VLOOKUP(B20,[1]Balance_Gatún!$A$13:$AD$5087,17)/35.32 -> 0 | K20: =+VLOOKUP(B20,[1]Balance_Gatún!$A$13:$AC$5087,10) -> 26 | L20: =+VLOOKUP(B20,[1]Balance_Gatún!$A$13:$AC$5087,11) -> XFILL_PMG50% | M20: =+VLOOKUP(B20,[1]Balance_Gatún!$A$13:$AC$5087,12) -> 10 | N20: =+VLOOKUP(B20,[1]Balance_Gatún!$A$13:$AC$5087,13) -> TA+CCL50% | O20: =+VLOOKUP(B20,[1]Balance_Gatún!$A$13:$AC$5087,14)/408.7 -> 7.5645659 | P20: =+VLOOKUP(B20,[1]Balance_Madden!$A$12:$V$5087,12)/35.32 -> 1.2747738 | Q20: =+VLOOKUP(B20,[1]Balance_Gatún!$A$13:$AD$5087,15)/35.32 -> 14.294745 | R20: =+VLOOKUP(B20,[1]Balance_Madden!$A$12:$V$5087,14)/35.32 -> 70.380097 | S20: =[1]Balance_Gatún!X19/35.32 -> 113.46799 | T20: 64.873997 | U20: 77.131752 | V20: =LOOKUP(D20,[1]Parámetros!$A$7:$A$24,[1]Parámetros!$B$7:$B$24) -> 49.5 | W20: =IF(V20<>V19,"Cambio Calado","") | X20: =IF(W20<>"",INT(A20),"") | Y20: =IF($W20="Cambio Calado",COUNTIF($W$14:W20,"Cambio Calado"),"") | Z20: =IF($W20="Cambio Calado",$X20,"") | AA20: =IF($W20="Cambio Calado",$V20,"") | AB20: =IFERROR(LOOKUP($A20,$Z$14:$Z20,$AA$14:$AA20),$U20) -> 49.5 | AC20: =IFERROR($A21-LOOKUP($A21,$Z$14:$Z20),"") -> 7 | AD20: {=IF(B20<>"",80,_xludf.NA())} -> 80 | AF20: =IFERROR(INDEX($X$14:$X$197,MATCH(ROWS($AF$14:AF20),$Y$14:$Y$197,0)),"") -> 46296 | AG20: =IFERROR(INDEX($V$14:$V$197,MATCH(ROWS($AF$14:AF20),$Y$14:$Y$197,0)),"") -> 49.5 | AH20: =IFERROR(INDEX($X$14:$X$197,MATCH(ROWS($AF$14:AF20)+1,$Y$14:$Y$197,0))-AF20,"") -> 22 | AI20: =IF(AF20="","","Cambio Calado") -> Cambio Calado
A21: =+INT(B21) -> 46211 | B21: =+[1]Balance_Madden!A19 -> 46211 | C21: =+VLOOKUP(B21,[1]Balance_Madden!$A$12:$E$5000,2) -> 224.8 | D21: =+VLOOKUP(B21,[1]Balance_Gatún!$A$13:$E$5087,2) -> 84.792 | E21: =+VLOOKUP(B21,[1]Balance_Madden!$A$12:$E$5087,5)/35.32 -> 33.517016 | F21: =+VLOOKUP(B21,[1]Balance_Gatún!$A$13:$E$5087,5)/35.32 -> 37.161495 | G21: =+VLOOKUP(B21,[1]Balance_Madden!$A$12:$K$5087,9)/111 -> 18.09009 | H21: =+VLOOKUP(B21,[1]Balance_Gatún!$A$13:$U$5087,21)/186 -> 0 | I21: =+(VLOOKUP(B21,[1]Balance_Madden!$A$12:$K$5087,10)/35.32)+VLOOKUP(B21,[1]Balance_Madden!$A$12:$K$5087,11)/35.32 -> 0 | J21: =+VLOOKUP(B21,[1]Balance_Gatún!$A$13:$AD$5087,23)/35.32+ VLOOKUP(B21,[1]Balance_Gatún!$A$13:$AD$5087,17)/35.32 -> 0 | K21: =+VLOOKUP(B21,[1]Balance_Gatún!$A$13:$AC$5087,10) -> 26 | L21: =+VLOOKUP(B21,[1]Balance_Gatún!$A$13:$AC$5087,11) -> XFILL_PMG50% | M21: =+VLOOKUP(B21,[1]Balance_Gatún!$A$13:$AC$5087,12) -> 10 | N21: =+VLOOKUP(B21,[1]Balance_Gatún!$A$13:$AC$5087,13) -> TA+CCL50% | O21: =+VLOOKUP(B21,[1]Balance_Gatún!$A$13:$AC$5087,14)/408.7 -> 7.5562527 | P21: =+VLOOKUP(B21,[1]Balance_Madden!$A$12:$V$5087,12)/35.32 -> 1.4874072 | Q21: =+VLOOKUP(B21,[1]Balance_Gatún!$A$13:$AD$5087,15)/35.32 -> 16.75445 | R21: =+VLOOKUP(B21,[1]Balance_Madden!$A$12:$V$5087,14)/35.32 -> 70.59273 | S21: =[1]Balance_Gatún!X20/35.32 -> 115.8315 | T21: 45.523295 | U21: 59.964628 | V21: =LOOKUP(D21,[1]Parámetros!$A$7:$A$24,[1]Parámetros!$B$7:$B$24) -> 49.5 | W21: =IF(V21<>V20,"Cambio Calado","") | X21: =IF(W21<>"",INT(A21),"") | Y21: =IF($W21="Cambio Calado",COUNTIF($W$14:W21,"Cambio Calado"),"") | Z21: =IF($W21="Cambio Calado",$X21,"") | AA21: =IF($W21="Cambio Calado",$V21,"") | AB21: =IFERROR(LOOKUP($A21,$Z$14:$Z21,$AA$14:$AA21),$U21) -> 49.5 | AC21: =IFERROR($A22-LOOKUP($A22,$Z$14:$Z21),"") -> 8 | AD21: {=IF(B21<>"",80,_xludf.NA())} -> 80 | AF21: =IFERROR(INDEX($X$14:$X$197,MATCH(ROWS($AF$14:AF21),$Y$14:$Y$197,0)),"") -> 46318 | AG21: =IFERROR(INDEX($V$14:$V$197,MATCH(ROWS($AF$14:AF21),$Y$14:$Y$197,0)),"") -> 49 | AH21: =IFERROR(INDEX($X$14:$X$197,MATCH(ROWS($AF$14:AF21)+1,$Y$14:$Y$197,0))-AF21,"") -> 3 | AI21: =IF(AF21="","","Cambio Calado") -> Cambio Calado
A22: =+INT(B22) -> 46212 | B22: =+[1]Balance_Madden!A20 -> 46212 | C22: =+VLOOKUP(B22,[1]Balance_Madden!$A$12:$E$5000,2) -> 224.49 | D22: =+VLOOKUP(B22,[1]Balance_Gatún!$A$13:$E$5087,2) -> 84.816 | E22: =+VLOOKUP(B22,[1]Balance_Madden!$A$12:$E$5087,5)/35.32 -> 31.647197 | F22: =+VLOOKUP(B22,[1]Balance_Gatún!$A$13:$E$5087,5)/35.32 -> 36.362854 | G22: =+VLOOKUP(B22,[1]Balance_Madden!$A$12:$K$5087,9)/111 -> 18.09009 | H22: =+VLOOKUP(B22,[1]Balance_Gatún!$A$13:$U$5087,21)/186 -> 0 | I22: =+(VLOOKUP(B22,[1]Balance_Madden!$A$12:$K$5087,10)/35.32)+VLOOKUP(B22,[1]Balance_Madden!$A$12:$K$5087,11)/35.32 -> 0 | J22: =+VLOOKUP(B22,[1]Balance_Gatún!$A$13:$AD$5087,23)/35.32+ VLOOKUP(B22,[1]Balance_Gatún!$A$13:$AD$5087,17)/35.32 -> 0 | K22: =+VLOOKUP(B22,[1]Balance_Gatún!$A$13:$AC$5087,10) -> 26 | L22: =+VLOOKUP(B22,[1]Balance_Gatún!$A$13:$AC$5087,11) -> XFILL_PMG50% | M22: =+VLOOKUP(B22,[1]Balance_Gatún!$A$13:$AC$5087,12) -> 10 | N22: =+VLOOKUP(B22,[1]Balance_Gatún!$A$13:$AC$5087,13) -> TA+CCL50% | O22: =+VLOOKUP(B22,[1]Balance_Gatún!$A$13:$AC$5087,14)/408.7 -> 7.5616451 | P22: =+VLOOKUP(B22,[1]Balance_Madden!$A$12:$V$5087,12)/35.32 -> 3.9966202 | Q22: =+VLOOKUP(B22,[1]Balance_Gatún!$A$13:$AD$5087,15)/35.32 -> 45.23779 | R22: =+VLOOKUP(B22,[1]Balance_Madden!$A$12:$V$5087,14)/35.32 -> 73.101943 | S22: =[1]Balance_Gatún!X21/35.32 -> 144.37724 | T22: 24.754017 | U22: 38.619126 | V22: =LOOKUP(D22,[1]Parámetros!$A$7:$A$24,[1]Parámetros!$B$7:$B$24) -> 49.5 | W22: =IF(V22<>V21,"Cambio Calado","") | X22: =IF(W22<>"",INT(A22),"") | Y22: =IF($W22="Cambio Calado",COUNTIF($W$14:W22,"Cambio Calado"),"") | Z22: =IF($W22="Cambio Calado",$X22,"") | AA22: =IF($W22="Cambio Calado",$V22,"") | AB22: =IFERROR(LOOKUP($A22,$Z$14:$Z22,$AA$14:$AA22),$U22) -> 49.5 | AC22: =IFERROR($A23-LOOKUP($A23,$Z$14:$Z22),"") -> 9 | AD22: {=IF(B22<>"",80,_xludf.NA())} -> 80 | AF22: =IFERROR(INDEX($X$14:$X$197,MATCH(ROWS($AF$14:AF22),$Y$14:$Y$197,0)),"") -> 46321 | AG22: =IFERROR(INDEX($V$14:$V$197,MATCH(ROWS($AF$14:AF22),$Y$14:$Y$197,0)),"") -> 49.5 | AH22: =IFERROR(INDEX($X$14:$X$197,MATCH(ROWS($AF$14:AF22)+1,$Y$14:$Y$197,0))-AF22,"") -> 1 | AI22: =IF(AF22="","","Cambio Calado") -> Cambio Calado
A23: =+INT(B23) -> 46213 | B23: =+[1]Balance_Madden!A21 -> 46213 | C23: =+VLOOKUP(B23,[1]Balance_Madden!$A$12:$E$5000,2) -> 224.17 | D23: =+VLOOKUP(B23,[1]Balance_Gatún!$A$13:$E$5087,2) -> 84.788 | E23: =+VLOOKUP(B23,[1]Balance_Madden!$A$12:$E$5087,5)/35.32 -> 30.107333 | F23: =+VLOOKUP(B23,[1]Balance_Gatún!$A$13:$E$5087,5)/35.32 -> 33.400142 | G23: =+VLOOKUP(B23,[1]Balance_Madden!$A$12:$K$5087,9)/111 -> 18.279279 | H23: =+VLOOKUP(B23,[1]Balance_Gatún!$A$13:$U$5087,21)/186 -> 0 | I23: =+(VLOOKUP(B23,[1]Balance_Madden!$A$12:$K$5087,10)/35.32)+VLOOKUP(B23,[1]Balance_Madden!$A$12:$K$5087,11)/35.32 -> 0 | J23: =+VLOOKUP(B23,[1]Balance_Gatún!$A$13:$AD$5087,23)/35.32+ VLOOKUP(B23,[1]Balance_Gatún!$A$13:$AD$5087,17)/35.32 -> 0 | K23: =+VLOOKUP(B23,[1]Balance_Gatún!$A$13:$AC$5087,10) -> 26 | L23: =+VLOOKUP(B23,[1]Balance_Gatún!$A$13:$AC$5087,11) -> XFILL_PMG50% | M23: =+VLOOKUP(B23,[1]Balance_Gatún!$A$13:$AC$5087,12) -> 10 | N23: =+VLOOKUP(B23,[1]Balance_Gatún!$A$13:$AC$5087,13) -> TA+CCL50% | O23: =+VLOOKUP(B23,[1]Balance_Gatún!$A$13:$AC$5087,14)/408.7 -> 7.555354 | P23: =+VLOOKUP(B23,[1]Balance_Madden!$A$12:$V$5087,12)/35.32 -> 1.0205909 | Q23: =+VLOOKUP(B23,[1]Balance_Gatún!$A$13:$AD$5087,15)/35.32 -> 11.602479 | R23: =+VLOOKUP(B23,[1]Balance_Madden!$A$12:$V$5087,14)/35.32 -> 70.720478 | S23: =[1]Balance_Gatún!X22/35.32 -> 110.66913 | T23: 78.979501 | U23: 32.01287 | V23: =LOOKUP(D23,[1]Parámetros!$A$7:$A$24,[1]Parámetros!$B$7:$B$24) -> 49.5 | W23: =IF(V23<>V22,"Cambio Calado","") | X23: =IF(W23<>"",INT(A23),"") | Y23: =IF($W23="Cambio Calado",COUNTIF($W$14:W23,"Cambio Calado"),"") | Z23: =IF($W23="Cambio Calado",$X23,"") | AA23: =IF($W23="Cambio Calado",$V23,"") | AB23: =IFERROR(LOOKUP($A23,$Z$14:$Z23,$AA$14:$AA23),$U23) -> 49.5 | AC23: =IFERROR($A24-LOOKUP($A24,$Z$14:$Z23),"") -> 10 | AD23: {=IF(B23<>"",80,_xludf.NA())} -> 80 | AF23: =IFERROR(INDEX($X$14:$X$197,MATCH(ROWS($AF$14:AF23),$Y$14:$Y$197,0)),"") -> 46322 | AG23: =IFERROR(INDEX($V$14:$V$197,MATCH(ROWS($AF$14:AF23),$Y$14:$Y$197,0)),"") -> 49 | AH23: =IFERROR(INDEX($X$14:$X$197,MATCH(ROWS($AF$14:AF23)+1,$Y$14:$Y$197,0))-AF23,"") -> 46 | AI23: =IF(AF23="","","Cambio Calado") -> Cambio Calado
A24: =+INT(B24) -> 46214 | B24: =+[1]Balance_Madden!A22 -> 46214 | C24: =+VLOOKUP(B24,[1]Balance_Madden!$A$12:$E$5000,2) -> 223.85 | D24: =+VLOOKUP(B24,[1]Balance_Gatún!$A$13:$E$5087,2) -> 84.766 | E24: =+VLOOKUP(B24,[1]Balance_Madden!$A$12:$E$5087,5)/35.32 -> 29.312316 | F24: =+VLOOKUP(B24,[1]Balance_Gatún!$A$13:$E$5087,5)/35.32 -> 23.855889 | G24: =+VLOOKUP(B24,[1]Balance_Madden!$A$12:$K$5087,9)/111 -> 18.279279 | H24: =+VLOOKUP(B24,[1]Balance_Gatún!$A$13:$U$5087,21)/186 -> 0 | I24: =+(VLOOKUP(B24,[1]Balance_Madden!$A$12:$K$5087,10)/35.32)+VLOOKUP(B24,[1]Balance_Madden!$A$12:$K$5087,11)/35.32 -> 0 | J24: =+VLOOKUP(B24,[1]Balance_Gatún!$A$13:$AD$5087,23)/35.32+ VLOOKUP(B24,[1]Balance_Gatún!$A$13:$AD$5087,17)/35.32 -> 0 | K24: =+VLOOKUP(B24,[1]Balance_Gatún!$A$13:$AC$5087,10) -> 26 | L24: =+VLOOKUP(B24,[1]Balance_Gatún!$A$13:$AC$5087,11) -> InnerGate | M24: =+VLOOKUP(B24,[1]Balance_Gatún!$A$13:$AC$5087,12) -> 10 | N24: =+VLOOKUP(B24,[1]Balance_Gatún!$A$13:$AC$5087,13) -> TA+CCL50% | O24: =+VLOOKUP(B24,[1]Balance_Gatún!$A$13:$AC$5087,14)/408.7 -> 8.2185092 | P24: =+VLOOKUP(B24,[1]Balance_Madden!$A$12:$V$5087,12)/35.32 -> 2.1538079 | Q24: =+VLOOKUP(B24,[1]Balance_Gatún!$A$13:$AD$5087,15)/35.32 -> 24.594348 | R24: =+VLOOKUP(B24,[1]Balance_Madden!$A$12:$V$5087,14)/35.32 -> 71.853695 | S24: =[1]Balance_Gatún!X23/35.32 -> 131.3346 | T24: 34.075479 | U24: 30.612644 | V24: =LOOKUP(D24,[1]Parámetros!$A$7:$A$24,[1]Parámetros!$B$7:$B$24) -> 49.5 | W24: =IF(V24<>V23,"Cambio Calado","") | X24: =IF(W24<>"",INT(A24),"") | Y24: =IF($W24="Cambio Calado",COUNTIF($W$14:W24,"Cambio Calado"),"") | Z24: =IF($W24="Cambio Calado",$X24,"") | AA24: =IF($W24="Cambio Calado",$V24,"") | AB24: =IFERROR(LOOKUP($A24,$Z$14:$Z24,$AA$14:$AA24),$U24) -> 49.5 | AC24: =IFERROR($A25-LOOKUP($A25,$Z$14:$Z24),"") -> 11 | AD24: {=IF(B24<>"",80,_xludf.NA())} -> 80 | AF24: =IFERROR(INDEX($X$14:$X$197,MATCH(ROWS($AF$14:AF24),$Y$14:$Y$197,0)),"") -> 46368 | AG24: =IFERROR(INDEX($V$14:$V$197,MATCH(ROWS($AF$14:AF24),$Y$14:$Y$197,0)),"") -> 48.5 | AH24: =IFERROR(INDEX($X$14:$X$197,MATCH(ROWS($AF$14:AF24)+1,$Y$14:$Y$197,0))-AF24,"") | AI24: =IF(AF24="","","Cambio Calado") -> Cambio Calado
A25: =+INT(B25) -> 46215 | B25: =+[1]Balance_Madden!A23 -> 46215 | C25: =+VLOOKUP(B25,[1]Balance_Madden!$A$12:$E$5000,2) -> 223.61 | D25: =+VLOOKUP(B25,[1]Balance_Gatún!$A$13:$E$5087,2) -> 84.774 | E25: =+VLOOKUP(B25,[1]Balance_Madden!$A$12:$E$5087,5)/35.32 -> 51.252746 | F25: =+VLOOKUP(B25,[1]Balance_Gatún!$A$13:$E$5087,5)/35.32 -> 26.910844 | G25: =+VLOOKUP(B25,[1]Balance_Madden!$A$12:$K$5087,9)/111 -> 18.279279 | H25: =+VLOOKUP(B25,[1]Balance_Gatún!$A$13:$U$5087,21)/186 -> 0 | I25: =+(VLOOKUP(B25,[1]Balance_Madden!$A$12:$K$5087,10)/35.32)+VLOOKUP(B25,[1]Balance_Madden!$A$12:$K$5087,11)/35.32 -> 0 | J25: =+VLOOKUP(B25,[1]Balance_Gatún!$A$13:$AD$5087,23)/35.32+ VLOOKUP(B25,[1]Balance_Gatún!$A$13:$AD$5087,17)/35.32 -> 0 | K25: =+VLOOKUP(B25,[1]Balance_Gatún!$A$13:$AC$5087,10) -> 26 | L25: =+VLOOKUP(B25,[1]Balance_Gatún!$A$13:$AC$5087,11) -> XFILL_PMG50% | M25: =+VLOOKUP(B25,[1]Balance_Gatún!$A$13:$AC$5087,12) -> 10 | N25: =+VLOOKUP(B25,[1]Balance_Gatún!$A$13:$AC$5087,13) -> TA+CCL50% | O25: =+VLOOKUP(B25,[1]Balance_Gatún!$A$13:$AC$5087,14)/408.7 -> 7.5522085 | P25: =+VLOOKUP(B25,[1]Balance_Madden!$A$12:$V$5087,12)/35.32 -> 1.4015428 | Q25: =+VLOOKUP(B25,[1]Balance_Gatún!$A$13:$AD$5087,15)/35.32 -> 16.062773 | R25: =+VLOOKUP(B25,[1]Balance_Madden!$A$12:$V$5087,14)/35.32 -> 71.10143 | S25: =[1]Balance_Gatún!X24/35.32 -> 115.09303 | T25: 23.608364 | U25: 36.883276 | V25: =LOOKUP(D25,[1]Parámetros!$A$7:$A$24,[1]Parámetros!$B$7:$B$24) -> 49.5 | W25: =IF(V25<>V24,"Cambio Calado","") | X25: =IF(W25<>"",INT(A25),"") | Y25: =IF($W25="Cambio Calado",COUNTIF($W$14:W25,"Cambio Calado"),"") | Z25: =IF($W25="Cambio Calado",$X25,"") | AA25: =IF($W25="Cambio Calado",$V25,"") | AB25: =IFERROR(LOOKUP($A25,$Z$14:$Z25,$AA$14:$AA25),$U25) -> 49.5 | AC25: =IFERROR($A26-LOOKUP($A26,$Z$14:$Z25),"") -> 12 | AD25: {=IF(B25<>"",80,_xludf.NA())} -> 80 | AF25: =IFERROR(INDEX($X$14:$X$197,MATCH(ROWS($AF$14:AF25),$Y$14:$Y$197,0)),"") | AG25: =IFERROR(INDEX($V$14:$V$197,MATCH(ROWS($AF$14:AF25),$Y$14:$Y$197,0)),"") | AH25: =IFERROR(INDEX($X$14:$X$197,MATCH(ROWS($AF$14:AF25)+1,$Y$14:$Y$197,0))-AF25,"") | AI25: =IF(AF25="","","Cambio Calado")
A26: =+INT(B26) -> 46216 | B26: =+[1]Balance_Madden!A24 -> 46216 | C26: =+VLOOKUP(B26,[1]Balance_Madden!$A$12:$E$5000,2) -> 223.62 | D26: =+VLOOKUP(B26,[1]Balance_Gatún!$A$13:$E$5087,2) -> 84.779 | E26: =+VLOOKUP(B26,[1]Balance_Madden!$A$12:$E$5087,5)/35.32 -> 89.397452 | F26: =+VLOOKUP(B26,[1]Balance_Gatún!$A$13:$E$5087,5)/35.32 -> 48.186863 | G26: =+VLOOKUP(B26,[1]Balance_Madden!$A$12:$K$5087,9)/111 -> 18.279279 | H26: =+VLOOKUP(B26,[1]Balance_Gatún!$A$13:$U$5087,21)/186 -> 0 | I26: =+(VLOOKUP(B26,[1]Balance_Madden!$A$12:$K$5087,10)/35.32)+VLOOKUP(B26,[1]Balance_Madden!$A$12:$K$5087,11)/35.32 -> 0 | J26: =+VLOOKUP(B26,[1]Balance_Gatún!$A$13:$AD$5087,23)/35.32+ VLOOKUP(B26,[1]Balance_Gatún!$A$13:$AD$5087,17)/35.32 -> 0 | K26: =+VLOOKUP(B26,[1]Balance_Gatún!$A$13:$AC$5087,10) -> 26 | L26: =+VLOOKUP(B26,[1]Balance_Gatún!$A$13:$AC$5087,11) -> InnerGate | M26: =+VLOOKUP(B26,[1]Balance_Gatún!$A$13:$AC$5087,12) -> 10 | N26: =+VLOOKUP(B26,[1]Balance_Gatún!$A$13:$AC$5087,13) -> TA+CCL50% | O26: =+VLOOKUP(B26,[1]Balance_Gatún!$A$13:$AC$5087,14)/408.7 -> 8.2217169 | P26: =+VLOOKUP(B26,[1]Balance_Madden!$A$12:$V$5087,12)/35.32 -> 1.4923302 | Q26: =+VLOOKUP(B26,[1]Balance_Gatún!$A$13:$AD$5087,15)/35.32 -> 17.101821 | R26: =+VLOOKUP(B26,[1]Balance_Madden!$A$12:$V$5087,14)/35.32 -> 71.192217 | S26: =[1]Balance_Gatún!X25/35.32 -> 123.87919 | T26: 65.353857 | U26: 111.76988 | V26: =LOOKUP(D26,[1]Parámetros!$A$7:$A$24,[1]Parámetros!$B$7:$B$24) -> 49.5 | W26: =IF(V26<>V25,"Cambio Calado","") | X26: =IF(W26<>"",INT(A26),"") | Y26: =IF($W26="Cambio Calado",COUNTIF($W$14:W26,"Cambio Calado"),"") | Z26: =IF($W26="Cambio Calado",$X26,"") | AA26: =IF($W26="Cambio Calado",$V26,"") | AB26: =IFERROR(LOOKUP($A26,$Z$14:$Z26,$AA$14:$AA26),$U26) -> 49.5 | AC26: =IFERROR($A27-LOOKUP($A27,$Z$14:$Z26),"") -> 13 | AD26: {=IF(B26<>"",80,_xludf.NA())} -> 80 | AF26: =IFERROR(INDEX($X$14:$X$197,MATCH(ROWS($AF$14:AF26),$Y$14:$Y$197,0)),"") | AG26: =IFERROR(INDEX($V$14:$V$197,MATCH(ROWS($AF$14:AF26),$Y$14:$Y$197,0)),"") | AH26: =IFERROR(INDEX($X$14:$X$197,MATCH(ROWS($AF$14:AF26)+1,$Y$14:$Y$197,0))-AF26,"") | AI26: =IF(AF26="","","Cambio Calado")
A27: =+INT(B27) -> 46217 | B27: =+[1]Balance_Madden!A25 -> 46217 | C27: =+VLOOKUP(B27,[1]Balance_Madden!$A$12:$E$5000,2) -> 223.37 | D27: =+VLOOKUP(B27,[1]Balance_Gatún!$A$13:$E$5087,2) -> 84.763 | E27: =+VLOOKUP(B27,[1]Balance_Madden!$A$12:$E$5087,5)/35.32 -> 45.87214 | F27: =+VLOOKUP(B27,[1]Balance_Gatún!$A$13:$E$5087,5)/35.32 -> 41.884428 | G27: =+VLOOKUP(B27,[1]Balance_Madden!$A$12:$K$5087,9)/111 -> 18.279279 | H27: =+VLOOKUP(B27,[1]Balance_Gatún!$A$13:$U$5087,21)/186 -> 0 | I27: =+(VLOOKUP(B27,[1]Balance_Madden!$A$12:$K$5087,10)/35.32)+VLOOKUP(B27,[1]Balance_Madden!$A$12:$K$5087,11)/35.32 -> 0 | J27: =+VLOOKUP(B27,[1]Balance_Gatún!$A$13:$AD$5087,23)/35.32+ VLOOKUP(B27,[1]Balance_Gatún!$A$13:$AD$5087,17)/35.32 -> 0 | K27: =+VLOOKUP(B27,[1]Balance_Gatún!$A$13:$AC$5087,10) -> 26 | L27: =+VLOOKUP(B27,[1]Balance_Gatún!$A$13:$AC$5087,11) -> XFILL_PMG50% | M27: =+VLOOKUP(B27,[1]Balance_Gatún!$A$13:$AC$5087,12) -> 10 | N27: =+VLOOKUP(B27,[1]Balance_Gatún!$A$13:$AC$5087,13) -> TA+CCL50% | O27: =+VLOOKUP(B27,[1]Balance_Gatún!$A$13:$AC$5087,14)/408.7 -> 7.549737 | P27: =+VLOOKUP(B27,[1]Balance_Madden!$A$12:$V$5087,12)/35.32 -> 1.1393534 | Q27: =+VLOOKUP(B27,[1]Balance_Gatún!$A$13:$AD$5087,15)/35.32 -> 13.102578 | R27: =+VLOOKUP(B27,[1]Balance_Madden!$A$12:$V$5087,14)/35.32 -> 70.83924 | S27: =[1]Balance_Gatún!X26/35.32 -> 112.10423 | T27: 57.198382 | U27: 57.786751 | V27: =LOOKUP(D27,[1]Parámetros!$A$7:$A$24,[1]Parámetros!$B$7:$B$24) -> 49.5 | W27: =IF(V27<>V26,"Cambio Calado","") | X27: =IF(W27<>"",INT(A27),"") | Y27: =IF($W27="Cambio Calado",COUNTIF($W$14:W27,"Cambio Calado"),"") | Z27: =IF($W27="Cambio Calado",$X27,"") | AA27: =IF($W27="Cambio Calado",$V27,"") | AB27: =IFERROR(LOOKUP($A27,$Z$14:$Z27,$AA$14:$AA27),$U27) -> 49.5 | AC27: =IFERROR($A28-LOOKUP($A28,$Z$14:$Z27),"") -> 14 | AD27: {=IF(B27<>"",80,_xludf.NA())} -> 80 | AF27: =IFERROR(INDEX($X$14:$X$197,MATCH(ROWS($AF$14:AF27),$Y$14:$Y$197,0)),"") | AG27: =IFERROR(INDEX($V$14:$V$197,MATCH(ROWS($AF$14:AF27),$Y$14:$Y$197,0)),"") | AH27: =IFERROR(INDEX($X$14:$X$197,MATCH(ROWS($AF$14:AF27)+1,$Y$14:$Y$197,0))-AF27,"") | AI27: =IF(AF27="","","Cambio Calado")
A28: =+INT(B28) -> 46218 | B28: =+[1]Balance_Madden!A26 -> 46218 | C28: =+VLOOKUP(B28,[1]Balance_Madden!$A$12:$E$5000,2) -> 223.05 | D28: =+VLOOKUP(B28,[1]Balance_Gatún!$A$13:$E$5087,2) -> 84.728 | E28: =+VLOOKUP(B28,[1]Balance_Madden!$A$12:$E$5087,5)/35.32 -> 37.128652 | F28: =+VLOOKUP(B28,[1]Balance_Gatún!$A$13:$E$5087,5)/35.32 -> 72.804473 | G28: =+VLOOKUP(B28,[1]Balance_Madden!$A$12:$K$5087,9)/111 -> 18.279279 | H28: =+VLOOKUP(B28,[1]Balance_Gatún!$A$13:$U$5087,21)/186 -> 0 | I28: =+(VLOOKUP(B28,[1]Balance_Madden!$A$12:$K$5087,10)/35.32)+VLOOKUP(B28,[1]Balance_Madden!$A$12:$K$5087,11)/35.32 -> 0 | J28: =+VLOOKUP(B28,[1]Balance_Gatún!$A$13:$AD$5087,23)/35.32+ VLOOKUP(B28,[1]Balance_Gatún!$A$13:$AD$5087,17)/35.32 -> 0 | K28: =+VLOOKUP(B28,[1]Balance_Gatún!$A$13:$AC$5087,10) -> 26 | L28: =+VLOOKUP(B28,[1]Balance_Gatún!$A$13:$AC$5087,11) -> InnerGate | M28: =+VLOOKUP(B28,[1]Balance_Gatún!$A$13:$AC$5087,12) -> 10 | N28: =+VLOOKUP(B28,[1]Balance_Gatún!$A$13:$AC$5087,13) -> TA+CCL50% | O28: =+VLOOKUP(B28,[1]Balance_Gatún!$A$13:$AC$5087,14)/408.7 -> 8.209133 | P28: =+VLOOKUP(B28,[1]Balance_Madden!$A$12:$V$5087,12)/35.32 -> 1.4920444 | Q28: =+VLOOKUP(B28,[1]Balance_Gatún!$A$13:$AD$5087,15)/35.32 -> 17.232633 | R28: =+VLOOKUP(B28,[1]Balance_Madden!$A$12:$V$5087,14)/35.32 -> 71.191931 | S28: =[1]Balance_Gatún!X27/35.32 -> 123.86439 | T28: 32.814571 | U28: 32.088755 | V28: =LOOKUP(D28,[1]Parámetros!$A$7:$A$24,[1]Parámetros!$B$7:$B$24) -> 49.5 | W28: =IF(V28<>V27,"Cambio Calado","") | X28: =IF(W28<>"",INT(A28),"") | Y28: =IF($W28="Cambio Calado",COUNTIF($W$14:W28,"Cambio Calado"),"") | Z28: =IF($W28="Cambio Calado",$X28,"") | AA28: =IF($W28="Cambio Calado",$V28,"") | AB28: =IFERROR(LOOKUP($A28,$Z$14:$Z28,$AA$14:$AA28),$U28) -> 49.5 | AC28: =IFERROR($A29-LOOKUP($A29,$Z$14:$Z28),"") -> 15 | AD28: {=IF(B28<>"",80,_xludf.NA())} -> 80
A29: =+INT(B29) -> 46219 | B29: =+[1]Balance_Madden!A27 -> 46219 | C29: =+VLOOKUP(B29,[1]Balance_Madden!$A$12:$E$5000,2) -> 222.7 | D29: =+VLOOKUP(B29,[1]Balance_Gatún!$A$13:$E$5087,2) -> 84.692 | E29: =+VLOOKUP(B29,[1]Balance_Madden!$A$12:$E$5087,5)/35.32 -> 45.103482 | F29: =+VLOOKUP(B29,[1]Balance_Gatún!$A$13:$E$5087,5)/35.32 -> 23.865345 | G29: =+VLOOKUP(B29,[1]Balance_Madden!$A$12:$K$5087,9)/111 -> 18.279279 | H29: =+VLOOKUP(B29,[1]Balance_Gatún!$A$13:$U$5087,21)/186 -> 0 | I29: =+(VLOOKUP(B29,[1]Balance_Madden!$A$12:$K$5087,10)/35.32)+VLOOKUP(B29,[1]Balance_Madden!$A$12:$K$5087,11)/35.32 -> 0 | J29: =+VLOOKUP(B29,[1]Balance_Gatún!$A$13:$AD$5087,23)/35.32+ VLOOKUP(B29,[1]Balance_Gatún!$A$13:$AD$5087,17)/35.32 -> 0 | K29: =+VLOOKUP(B29,[1]Balance_Gatún!$A$13:$AC$5087,10) -> 26 | L29: =+VLOOKUP(B29,[1]Balance_Gatún!$A$13:$AC$5087,11) -> XFILL_PMG50% | M29: =+VLOOKUP(B29,[1]Balance_Gatún!$A$13:$AC$5087,12) -> 10 | N29: =+VLOOKUP(B29,[1]Balance_Gatún!$A$13:$AC$5087,13) -> TA+CCL50% | O29: =+VLOOKUP(B29,[1]Balance_Gatún!$A$13:$AC$5087,14)/408.7 -> 7.5337847 | P29: =+VLOOKUP(B29,[1]Balance_Madden!$A$12:$V$5087,12)/35.32 -> 1.8619464 | Q29: =+VLOOKUP(B29,[1]Balance_Gatún!$A$13:$AD$5087,15)/35.32 -> 21.60743 | R29: =+VLOOKUP(B29,[1]Balance_Madden!$A$12:$V$5087,14)/35.32 -> 71.561833 | S29: =[1]Balance_Gatún!X28/35.32 -> 120.4245 | T29: 35.329887 | U29: 44.774103 | V29: =LOOKUP(D29,[1]Parámetros!$A$7:$A$24,[1]Parámetros!$B$7:$B$24) -> 49.5 | W29: =IF(V29<>V28,"Cambio Calado","") | X29: =IF(W29<>"",INT(A29),"") | Y29: =IF($W29="Cambio Calado",COUNTIF($W$14:W29,"Cambio Calado"),"") | Z29: =IF($W29="Cambio Calado",$X29,"") | AA29: =IF($W29="Cambio Calado",$V29,"") | AB29: =IFERROR(LOOKUP($A29,$Z$14:$Z29,$AA$14:$AA29),$U29) -> 49.5 | AC29: =IFERROR($A30-LOOKUP($A30,$Z$14:$Z29),"") -> 16 | AD29: {=IF(B29<>"",80,_xludf.NA())} -> 80
A30: =+INT(B30) -> 46220 | B30: =+[1]Balance_Madden!A28 -> 46220 | C30: =+VLOOKUP(B30,[1]Balance_Madden!$A$12:$E$5000,2) -> 222.35 | D30: =+VLOOKUP(B30,[1]Balance_Gatún!$A$13:$E$5087,2) -> 84.642 | E30: =+VLOOKUP(B30,[1]Balance_Madden!$A$12:$E$5087,5)/35.32 -> 33.285362 | F30: =+VLOOKUP(B30,[1]Balance_Gatún!$A$13:$E$5087,5)/35.32 -> 18.070498 | G30: =+VLOOKUP(B30,[1]Balance_Madden!$A$12:$K$5087,9)/111 -> 18.279279 | H30: =+VLOOKUP(B30,[1]Balance_Gatún!$A$13:$U$5087,21)/186 -> 0 | I30: =+(VLOOKUP(B30,[1]Balance_Madden!$A$12:$K$5087,10)/35.32)+VLOOKUP(B30,[1]Balance_Madden!$A$12:$K$5087,11)/35.32 -> 0 | J30: =+VLOOKUP(B30,[1]Balance_Gatún!$A$13:$AD$5087,23)/35.32+ VLOOKUP(B30,[1]Balance_Gatún!$A$13:$AD$5087,17)/35.32 -> 0 | K30: =+VLOOKUP(B30,[1]Balance_Gatún!$A$13:$AC$5087,10) -> 24 | L30: =+VLOOKUP(B30,[1]Balance_Gatún!$A$13:$AC$5087,11) -> InnerGate | M30: =+VLOOKUP(B30,[1]Balance_Gatún!$A$13:$AC$5087,12) -> 10 | N30: =+VLOOKUP(B30,[1]Balance_Gatún!$A$13:$AC$5087,13) -> TA+CCL50% | O30: =+VLOOKUP(B30,[1]Balance_Gatún!$A$13:$AC$5087,14)/408.7 -> 7.8220934 | P30: =+VLOOKUP(B30,[1]Balance_Madden!$A$12:$V$5087,12)/35.32 -> 0.64393744 | Q30: =+VLOOKUP(B30,[1]Balance_Gatún!$A$13:$AD$5087,15)/35.32 -> 7.5071503 | R30: =+VLOOKUP(B30,[1]Balance_Madden!$A$12:$V$5087,14)/35.32 -> 70.343824 | S30: =[1]Balance_Gatún!X29/35.32 -> 109.66034 | T30: 39.666815 | U30: 33.213387 | V30: =LOOKUP(D30,[1]Parámetros!$A$7:$A$24,[1]Parámetros!$B$7:$B$24) -> 49.5 | W30: =IF(V30<>V29,"Cambio Calado","") | X30: =IF(W30<>"",INT(A30),"") | Y30: =IF($W30="Cambio Calado",COUNTIF($W$14:W30,"Cambio Calado"),"") | Z30: =IF($W30="Cambio Calado",$X30,"") | AA30: =IF($W30="Cambio Calado",$V30,"") | AB30: =IFERROR(LOOKUP($A30,$Z$14:$Z30,$AA$14:$AA30),$U30) -> 49.5 | AC30: =IFERROR($A31-LOOKUP($A31,$Z$14:$Z30),"") -> 17 | AD30: {=IF(B30<>"",80,_xludf.NA())} -> 80
A31: =+INT(B31) -> 46221 | B31: =+[1]Balance_Madden!A29 -> 46221 | C31: =+VLOOKUP(B31,[1]Balance_Madden!$A$12:$E$5000,2) -> 221.96 | D31: =+VLOOKUP(B31,[1]Balance_Gatún!$A$13:$E$5087,2) -> 84.609 | E31: =+VLOOKUP(B31,[1]Balance_Madden!$A$12:$E$5087,5)/35.32 -> 34.897254 | F31: =+VLOOKUP(B31,[1]Balance_Gatún!$A$13:$E$5087,5)/35.32 -> 27.046206 | G31: =+VLOOKUP(B31,[1]Balance_Madden!$A$12:$K$5087,9)/111 -> 18.279279 | H31: =+VLOOKUP(B31,[1]Balance_Gatún!$A$13:$U$5087,21)/186 -> 0 | I31: =+(VLOOKUP(B31,[1]Balance_Madden!$A$12:$K$5087,10)/35.32)+VLOOKUP(B31,[1]Balance_Madden!$A$12:$K$5087,11)/35.32 -> 0 | J31: =+VLOOKUP(B31,[1]Balance_Gatún!$A$13:$AD$5087,23)/35.32+ VLOOKUP(B31,[1]Balance_Gatún!$A$13:$AD$5087,17)/35.32 -> 0 | K31: =+VLOOKUP(B31,[1]Balance_Gatún!$A$13:$AC$5087,10) -> 24 | L31: =+VLOOKUP(B31,[1]Balance_Gatún!$A$13:$AC$5087,11) -> XFILL_PMG50% | M31: =+VLOOKUP(B31,[1]Balance_Gatún!$A$13:$AC$5087,12) -> 10 | N31: =+VLOOKUP(B31,[1]Balance_Gatún!$A$13:$AC$5087,13) -> TA+CCL50% | O31: =+VLOOKUP(B31,[1]Balance_Gatún!$A$13:$AC$5087,14)/408.7 -> 7.2008722 | P31: =+VLOOKUP(B31,[1]Balance_Madden!$A$12:$V$5087,12)/35.32 -> 1.5847652 | Q31: =+VLOOKUP(B31,[1]Balance_Gatún!$A$13:$AD$5087,15)/35.32 -> 18.576054 | R31: =+VLOOKUP(B31,[1]Balance_Madden!$A$12:$V$5087,14)/35.32 -> 71.284652 | S31: =[1]Balance_Gatún!X30/35.32 -> 113.54087 | T31: 109.34132 | U31: 96.319888 | V31: =LOOKUP(D31,[1]Parámetros!$A$7:$A$24,[1]Parámetros!$B$7:$B$24) -> 49.5 | W31: =IF(V31<>V30,"Cambio Calado","") | X31: =IF(W31<>"",INT(A31),"") | Y31: =IF($W31="Cambio Calado",COUNTIF($W$14:W31,"Cambio Calado"),"") | Z31: =IF($W31="Cambio Calado",$X31,"") | AA31: =IF($W31="Cambio Calado",$V31,"") | AB31: =IFERROR(LOOKUP($A31,$Z$14:$Z31,$AA$14:$AA31),$U31) -> 49.5 | AC31: =IFERROR($A32-LOOKUP($A32,$Z$14:$Z31),"") -> 18 | AD31: {=IF(B31<>"",80,_xludf.NA())} -> 80
A32: =+INT(B32) -> 46222 | B32: =+[1]Balance_Madden!A30 -> 46222 | C32: =+VLOOKUP(B32,[1]Balance_Madden!$A$12:$E$5000,2) -> 222.77 | D32: =+VLOOKUP(B32,[1]Balance_Gatún!$A$13:$E$5087,2) -> 84.608 | E32: =+VLOOKUP(B32,[1]Balance_Madden!$A$12:$E$5087,5)/35.32 -> 30.083409 | F32: =+VLOOKUP(B32,[1]Balance_Gatún!$A$13:$E$5087,5)/35.32 -> 18.07769 | G32: =+VLOOKUP(B32,[1]Balance_Madden!$A$12:$K$5087,9)/111 -> 18.279279 | H32: =+VLOOKUP(B32,[1]Balance_Gatún!$A$13:$U$5087,21)/186 -> 0 | I32: =+(VLOOKUP(B32,[1]Balance_Madden!$A$12:$K$5087,10)/35.32)+VLOOKUP(B32,[1]Balance_Madden!$A$12:$K$5087,11)/35.32 -> 0 | J32: =+VLOOKUP(B32,[1]Balance_Gatún!$A$13:$AD$5087,23)/35.32+ VLOOKUP(B32,[1]Balance_Gatún!$A$13:$AD$5087,17)/35.32 -> 0 | K32: =+VLOOKUP(B32,[1]Balance_Gatún!$A$13:$AC$5087,10) -> 24 | L32: =+VLOOKUP(B32,[1]Balance_Gatún!$A$13:$AC$5087,11) -> InnerGate | M32: =+VLOOKUP(B32,[1]Balance_Gatún!$A$13:$AC$5087,12) -> 10 | N32: =+VLOOKUP(B32,[1]Balance_Gatún!$A$13:$AC$5087,13) -> TA+CCL50% | O32: =+VLOOKUP(B32,[1]Balance_Gatún!$A$13:$AC$5087,14)/408.7 -> 7.8141472 | P32: =+VLOOKUP(B32,[1]Balance_Madden!$A$12:$V$5087,12)/35.32 -> 1.6074961 | Q32: =+VLOOKUP(B32,[1]Balance_Gatún!$A$13:$AD$5087,15)/35.32 -> 18.615218 | R32: =+VLOOKUP(B32,[1]Balance_Madden!$A$12:$V$5087,14)/35.32 -> 71.307383 | S32: =[1]Balance_Gatún!X31/35.32 -> 120.67646 | T32: 57.776922 | U32: 56.891582 | V32: =LOOKUP(D32,[1]Parámetros!$A$7:$A$24,[1]Parámetros!$B$7:$B$24) -> 49.5 | W32: =IF(V32<>V31,"Cambio Calado","") | X32: =IF(W32<>"",INT(A32),"") | Y32: =IF($W32="Cambio Calado",COUNTIF($W$14:W32,"Cambio Calado"),"") | Z32: =IF($W32="Cambio Calado",$X32,"") | AA32: =IF($W32="Cambio Calado",$V32,"") | AB32: =IFERROR(LOOKUP($A32,$Z$14:$Z32,$AA$14:$AA32),$U32) -> 49.5 | AC32: =IFERROR($A33-LOOKUP($A33,$Z$14:$Z32),"") -> 19 | AD32: {=IF(B32<>"",80,_xludf.NA())} -> 80
A33: =+INT(B33) -> 46223 | B33: =+[1]Balance_Madden!A31 -> 46223 | C33: =+VLOOKUP(B33,[1]Balance_Madden!$A$12:$E$5000,2) -> 222.84 | D33: =+VLOOKUP(B33,[1]Balance_Gatún!$A$13:$E$5087,2) -> 84.657 | E33: =+VLOOKUP(B33,[1]Balance_Madden!$A$12:$E$5087,5)/35.32 -> 40.911042 | F33: =+VLOOKUP(B33,[1]Balance_Gatún!$A$13:$E$5087,5)/35.32 -> 49.973698 | G33: =+VLOOKUP(B33,[1]Balance_Madden!$A$12:$K$5087,9)/111 -> 18.279279 | H33: =+VLOOKUP(B33,[1]Balance_Gatún!$A$13:$U$5087,21)/186 -> 0 | I33: =+(VLOOKUP(B33,[1]Balance_Madden!$A$12:$K$5087,10)/35.32)+VLOOKUP(B33,[1]Balance_Madden!$A$12:$K$5087,11)/35.32 -> 0 | J33: =+VLOOKUP(B33,[1]Balance_Gatún!$A$13:$AD$5087,23)/35.32+ VLOOKUP(B33,[1]Balance_Gatún!$A$13:$AD$5087,17)/35.32 -> 0 | K33: =+VLOOKUP(B33,[1]Balance_Gatún!$A$13:$AC$5087,10) -> 24 | L33: =+VLOOKUP(B33,[1]Balance_Gatún!$A$13:$AC$5087,11) -> XFILL_PMG50% | M33: =+VLOOKUP(B33,[1]Balance_Gatún!$A$13:$AC$5087,12) -> 10 | N33: =+VLOOKUP(B33,[1]Balance_Gatún!$A$13:$AC$5087,13) -> TA+CCL50% | O33: =+VLOOKUP(B33,[1]Balance_Gatún!$A$13:$AC$5087,14)/408.7 -> 7.2111129 | P33: =+VLOOKUP(B33,[1]Balance_Madden!$A$12:$V$5087,12)/35.32 -> 1.3289924 | Q33: =+VLOOKUP(B33,[1]Balance_Gatún!$A$13:$AD$5087,15)/35.32 -> 15.383611 | R33: =+VLOOKUP(B33,[1]Balance_Madden!$A$12:$V$5087,14)/35.32 -> 71.028879 | S33: =[1]Balance_Gatún!X32/35.32 -> 110.46693 | T33: 67.366791 | U33: 68.322361 | V33: =LOOKUP(D33,[1]Parámetros!$A$7:$A$24,[1]Parámetros!$B$7:$B$24) -> 49.5 | W33: =IF(V33<>V32,"Cambio Calado","") | X33: =IF(W33<>"",INT(A33),"") | Y33: =IF($W33="Cambio Calado",COUNTIF($W$14:W33,"Cambio Calado"),"") | Z33: =IF($W33="Cambio Calado",$X33,"") | AA33: =IF($W33="Cambio Calado",$V33,"") | AB33: =IFERROR(LOOKUP($A33,$Z$14:$Z33,$AA$14:$AA33),$U33) -> 49.5 | AC33: =IFERROR($A34-LOOKUP($A34,$Z$14:$Z33),"") -> 20 | AD33: {=IF(B33<>"",80,_xludf.NA())} -> 80
A34: =+INT(B34) -> 46224 | B34: =+[1]Balance_Madden!A32 -> 46224 | C34: =+VLOOKUP(B34,[1]Balance_Madden!$A$12:$E$5000,2) -> 222.59 | D34: =+VLOOKUP(B34,[1]Balance_Gatún!$A$13:$E$5087,2) -> 84.631 | E34: =+VLOOKUP(B34,[1]Balance_Madden!$A$12:$E$5087,5)/35.32 -> 86.306908 | F34: =+VLOOKUP(B34,[1]Balance_Gatún!$A$13:$E$5087,5)/35.32 -> 51.018318 | G34: =+VLOOKUP(B34,[1]Balance_Madden!$A$12:$K$5087,9)/111 -> 18.279279 | H34: =+VLOOKUP(B34,[1]Balance_Gatún!$A$13:$U$5087,21)/186 -> 0 | I34: =+(VLOOKUP(B34,[1]Balance_Madden!$A$12:$K$5087,10)/35.32)+VLOOKUP(B34,[1]Balance_Madden!$A$12:$K$5087,11)/35.32 -> 0 | J34: =+VLOOKUP(B34,[1]Balance_Gatún!$A$13:$AD$5087,23)/35.32+ VLOOKUP(B34,[1]Balance_Gatún!$A$13:$AD$5087,17)/35.32 -> 0 | K34: =+VLOOKUP(B34,[1]Balance_Gatún!$A$13:$AC$5087,10) -> 24 | L34: =+VLOOKUP(B34,[1]Balance_Gatún!$A$13:$AC$5087,11) -> InnerGate | M34: =+VLOOKUP(B34,[1]Balance_Gatún!$A$13:$AC$5087,12) -> 10 | N34: =+VLOOKUP(B34,[1]Balance_Gatún!$A$13:$AC$5087,13) -> TA+CCL50% | O34: =+VLOOKUP(B34,[1]Balance_Gatún!$A$13:$AC$5087,14)/408.7 -> 7.8195226 | P34: =+VLOOKUP(B34,[1]Balance_Madden!$A$12:$V$5087,12)/35.32 -> 1.556535 | Q34: =+VLOOKUP(B34,[1]Balance_Gatún!$A$13:$AD$5087,15)/35.32 -> 18.078859 | R34: =+VLOOKUP(B34,[1]Balance_Madden!$A$12:$V$5087,14)/35.32 -> 71.256422 | S34: =[1]Balance_Gatún!X33/35.32 -> 120.2023 | T34: 38.933113 | U34: 97.925639 | V34: =LOOKUP(D34,[1]Parámetros!$A$7:$A$24,[1]Parámetros!$B$7:$B$24) -> 49.5 | W34: =IF(V34<>V33,"Cambio Calado","") | X34: =IF(W34<>"",INT(A34),"") | Y34: =IF($W34="Cambio Calado",COUNTIF($W$14:W34,"Cambio Calado"),"") | Z34: =IF($W34="Cambio Calado",$X34,"") | AA34: =IF($W34="Cambio Calado",$V34,"") | AB34: =IFERROR(LOOKUP($A34,$Z$14:$Z34,$AA$14:$AA34),$U34) -> 49.5 | AC34: =IFERROR($A35-LOOKUP($A35,$Z$14:$Z34),"") -> 21 | AD34: {=IF(B34<>"",80,_xludf.NA())} -> 80
A35: =+INT(B35) -> 46225 | B35: =+[1]Balance_Madden!A33 -> 46225 | C35: =+VLOOKUP(B35,[1]Balance_Madden!$A$12:$E$5000,2) -> 223.53 | D35: =+VLOOKUP(B35,[1]Balance_Gatún!$A$13:$E$5087,2) -> 84.662 | E35: =+VLOOKUP(B35,[1]Balance_Madden!$A$12:$E$5087,5)/35.32 -> 35.697735 | F35: =+VLOOKUP(B35,[1]Balance_Gatún!$A$13:$E$5087,5)/35.32 -> 22.778511 | G35: =+VLOOKUP(B35,[1]Balance_Madden!$A$12:$K$5087,9)/111 -> 18.279279 | H35: =+VLOOKUP(B35,[1]Balance_Gatún!$A$13:$U$5087,21)/186 -> 0 | I35: =+(VLOOKUP(B35,[1]Balance_Madden!$A$12:$K$5087,10)/35.32)+VLOOKUP(B35,[1]Balance_Madden!$A$12:$K$5087,11)/35.32 -> 0 | J35: =+VLOOKUP(B35,[1]Balance_Gatún!$A$13:$AD$5087,23)/35.32+ VLOOKUP(B35,[1]Balance_Gatún!$A$13:$AD$5087,17)/35.32 -> 0 | K35: =+VLOOKUP(B35,[1]Balance_Gatún!$A$13:$AC$5087,10) -> 24 | L35: =+VLOOKUP(B35,[1]Balance_Gatún!$A$13:$AC$5087,11) -> XFILL_PMG50% | M35: =+VLOOKUP(B35,[1]Balance_Gatún!$A$13:$AC$5087,12) -> 10 | N35: =+VLOOKUP(B35,[1]Balance_Gatún!$A$13:$AC$5087,13) -> TA+CCL50% | O35: =+VLOOKUP(B35,[1]Balance_Gatún!$A$13:$AC$5087,14)/408.7 -> 7.2121797 | P35: =+VLOOKUP(B35,[1]Balance_Madden!$A$12:$V$5087,12)/35.32 -> 1.3174432 | Q35: =+VLOOKUP(B35,[1]Balance_Gatún!$A$13:$AD$5087,15)/35.32 -> 15.095317 | R35: =+VLOOKUP(B35,[1]Balance_Madden!$A$12:$V$5087,14)/35.32 -> 71.01733 | S35: =[1]Balance_Gatún!X34/35.32 -> 110.19098 | T35: 74.370157 | U35: 49.064243 | V35: =LOOKUP(D35,[1]Parámetros!$A$7:$A$24,[1]Parámetros!$B$7:$B$24) -> 49.5 | W35: =IF(V35<>V34,"Cambio Calado","") | X35: =IF(W35<>"",INT(A35),"") | Y35: =IF($W35="Cambio Calado",COUNTIF($W$14:W35,"Cambio Calado"),"") | Z35: =IF($W35="Cambio Calado",$X35,"") | AA35: =IF($W35="Cambio Calado",$V35,"") | AB35: =IFERROR(LOOKUP($A35,$Z$14:$Z35,$AA$14:$AA35),$U35) -> 49.5 | AC35: =IFERROR($A36-LOOKUP($A36,$Z$14:$Z35),"") -> 22 | AD35: {=IF(B35<>"",80,_xludf.NA())} -> 80
A36: =+INT(B36) -> 46226 | B36: =+[1]Balance_Madden!A34 -> 46226 | C36: =+VLOOKUP(B36,[1]Balance_Madden!$A$12:$E$5000,2) -> 225.2 | D36: =+VLOOKUP(B36,[1]Balance_Gatún!$A$13:$E$5087,2) -> 84.897 | E36: =+VLOOKUP(B36,[1]Balance_Madden!$A$12:$E$5087,5)/35.32 -> 29.441761 | F36: =+VLOOKUP(B36,[1]Balance_Gatún!$A$13:$E$5087,5)/35.32 -> 17.625 | G36: =+VLOOKUP(B36,[1]Balance_Madden!$A$12:$K$5087,9)/111 -> 18.279279 | H36: =+VLOOKUP(B36,[1]Balance_Gatún!$A$13:$U$5087,21)/186 -> 0 | I36: =+(VLOOKUP(B36,[1]Balance_Madden!$A$12:$K$5087,10)/35.32)+VLOOKUP(B36,[1]Balance_Madden!$A$12:$K$5087,11)/35.32 -> 0 | J36: =+VLOOKUP(B36,[1]Balance_Gatún!$A$13:$AD$5087,23)/35.32+ VLOOKUP(B36,[1]Balance_Gatún!$A$13:$AD$5087,17)/35.32 -> 0 | K36: =+VLOOKUP(B36,[1]Balance_Gatún!$A$13:$AC$5087,10) -> 24 | L36: =+VLOOKUP(B36,[1]Balance_Gatún!$A$13:$AC$5087,11) -> InnerGate | M36: =+VLOOKUP(B36,[1]Balance_Gatún!$A$13:$AC$5087,12) -> 10 | N36: =+VLOOKUP(B36,[1]Balance_Gatún!$A$13:$AC$5087,13) -> TA+CCL50% | O36: =+VLOOKUP(B36,[1]Balance_Gatún!$A$13:$AC$5087,14)/408.7 -> 7.8816901 | P36: =+VLOOKUP(B36,[1]Balance_Madden!$A$12:$V$5087,12)/35.32 -> 1.3362898 | Q36: =+VLOOKUP(B36,[1]Balance_Gatún!$A$13:$AD$5087,15)/35.32 -> 14.984352 | R36: =+VLOOKUP(B36,[1]Balance_Madden!$A$12:$V$5087,14)/35.32 -> 71.036177 | S36: =[1]Balance_Gatún!X35/35.32 -> 117.82715 | T36: 40.441723 | U36: 148.41343 | V36: =LOOKUP(D36,[1]Parámetros!$A$7:$A$24,[1]Parámetros!$B$7:$B$24) -> 49.5 | W36: =IF(V36<>V35,"Cambio Calado","") | X36: =IF(W36<>"",INT(A36),"") | Y36: =IF($W36="Cambio Calado",COUNTIF($W$14:W36,"Cambio Calado"),"") | Z36: =IF($W36="Cambio Calado",$X36,"") | AA36: =IF($W36="Cambio Calado",$V36,"") | AB36: =IFERROR(LOOKUP($A36,$Z$14:$Z36,$AA$14:$AA36),$U36) -> 49.5 | AC36: =IFERROR($A37-LOOKUP($A37,$Z$14:$Z36),"") -> 23 | AD36: {=IF(B36<>"",80,_xludf.NA())} -> 80
A37: =+INT(B37) -> 46227 | B37: =+[1]Balance_Madden!A35 -> 46227 | C37: =+VLOOKUP(B37,[1]Balance_Madden!$A$12:$E$5000,2) -> 225.84 | D37: =+VLOOKUP(B37,[1]Balance_Gatún!$A$13:$E$5087,2) -> 84.961 | E37: =+VLOOKUP(B37,[1]Balance_Madden!$A$12:$E$5087,5)/35.32 -> 26.795017 | F37: =+VLOOKUP(B37,[1]Balance_Gatún!$A$13:$E$5087,5)/35.32 -> 18.008041 | G37: =+VLOOKUP(B37,[1]Balance_Madden!$A$12:$K$5087,9)/111 -> 2.6666667 | H37: =+VLOOKUP(B37,[1]Balance_Gatún!$A$13:$U$5087,21)/186 -> 0 | I37: =+(VLOOKUP(B37,[1]Balance_Madden!$A$12:$K$5087,10)/35.32)+VLOOKUP(B37,[1]Balance_Madden!$A$12:$K$5087,11)/35.32 -> 0 | J37: =+VLOOKUP(B37,[1]Balance_Gatún!$A$13:$AD$5087,23)/35.32+ VLOOKUP(B37,[1]Balance_Gatún!$A$13:$AD$5087,17)/35.32 -> 0 | K37: =+VLOOKUP(B37,[1]Balance_Gatún!$A$13:$AC$5087,10) -> 24 | L37: =+VLOOKUP(B37,[1]Balance_Gatún!$A$13:$AC$5087,11) -> XFILL_PMG50% | M37: =+VLOOKUP(B37,[1]Balance_Gatún!$A$13:$AC$5087,12) -> 10 | N37: =+VLOOKUP(B37,[1]Balance_Gatún!$A$13:$AC$5087,13) -> TA+CCL50% | O37: =+VLOOKUP(B37,[1]Balance_Gatún!$A$13:$AC$5087,14)/408.7 -> 7.2759705 | P37: =+VLOOKUP(B37,[1]Balance_Madden!$A$12:$V$5087,12)/35.32 -> 0.88350459 | Q37: =+VLOOKUP(B37,[1]Balance_Gatún!$A$13:$AD$5087,15)/35.32 -> 9.8231208 | R37: =+VLOOKUP(B37,[1]Balance_Madden!$A$12:$V$5087,14)/35.32 -> 21.517706 | S37: =[1]Balance_Gatún!X36/35.32 -> 105.65693 | T37: 80.595522 | U37: 98.165732 | V37: =LOOKUP(D37,[1]Parámetros!$A$7:$A$24,[1]Parámetros!$B$7:$B$24) -> 49.5 | W37: =IF(V37<>V36,"Cambio Calado","") | X37: =IF(W37<>"",INT(A37),"") | Y37: =IF($W37="Cambio Calado",COUNTIF($W$14:W37,"Cambio Calado"),"") | Z37: =IF($W37="Cambio Calado",$X37,"") | AA37: =IF($W37="Cambio Calado",$V37,"") | AB37: =IFERROR(LOOKUP($A37,$Z$14:$Z37,$AA$14:$AA37),$U37) -> 49.5 | AC37: =IFERROR($A38-LOOKUP($A38,$Z$14:$Z37),"") -> 24 | AD37: {=IF(B37<>"",80,_xludf.NA())} -> 80
A38: =+INT(B38) -> 46228 | B38: =+[1]Balance_Madden!A36 -> 46228 | C38: =+VLOOKUP(B38,[1]Balance_Madden!$A$12:$E$5000,2) -> 226.14 | D38: =+VLOOKUP(B38,[1]Balance_Gatún!$A$13:$E$5087,2) -> 84.928 | E38: =+VLOOKUP(B38,[1]Balance_Madden!$A$12:$E$5087,5)/35.32 -> 33.078596 | F38: =+VLOOKUP(B38,[1]Balance_Gatún!$A$13:$E$5087,5)/35.32 -> 31.763335 | G38: =+VLOOKUP(B38,[1]Balance_Madden!$A$12:$K$5087,9)/111 -> 2.6666667 | H38: =+VLOOKUP(B38,[1]Balance_Gatún!$A$13:$U$5087,21)/186 -> 0 | I38: =+(VLOOKUP(B38,[1]Balance_Madden!$A$12:$K$5087,10)/35.32)+VLOOKUP(B38,[1]Balance_Madden!$A$12:$K$5087,11)/35.32 -> 0 | J38: =+VLOOKUP(B38,[1]Balance_Gatún!$A$13:$AD$5087,23)/35.32+ VLOOKUP(B38,[1]Balance_Gatún!$A$13:$AD$5087,17)/35.32 -> 0 | K38: =+VLOOKUP(B38,[1]Balance_Gatún!$A$13:$AC$5087,10) -> 24 | L38: =+VLOOKUP(B38,[1]Balance_Gatún!$A$13:$AC$5087,11) -> InnerGate | M38: =+VLOOKUP(B38,[1]Balance_Gatún!$A$13:$AC$5087,12) -> 10 | N38: =+VLOOKUP(B38,[1]Balance_Gatún!$A$13:$AC$5087,13) -> TA+CCL50% | O38: =+VLOOKUP(B38,[1]Balance_Gatún!$A$13:$AC$5087,14)/408.7 -> 7.8889352 | P38: =+VLOOKUP(B38,[1]Balance_Madden!$A$12:$V$5087,12)/35.32 -> 0.4058767 | Q38: =+VLOOKUP(B38,[1]Balance_Gatún!$A$13:$AD$5087,15)/35.32 -> 4.4912017 | R38: =+VLOOKUP(B38,[1]Balance_Madden!$A$12:$V$5087,14)/35.32 -> 21.040078 | S38: =[1]Balance_Gatún!X37/35.32 -> 107.41784 | T38: 49.325867 | U38: 47.918036 | V38: =LOOKUP(D38,[1]Parámetros!$A$7:$A$24,[1]Parámetros!$B$7:$B$24) -> 49.5 | W38: =IF(V38<>V37,"Cambio Calado","") | X38: =IF(W38<>"",INT(A38),"") | Y38: =IF($W38="Cambio Calado",COUNTIF($W$14:W38,"Cambio Calado"),"") | Z38: =IF($W38="Cambio Calado",$X38,"") | AA38: =IF($W38="Cambio Calado",$V38,"") | AB38: =IFERROR(LOOKUP($A38,$Z$14:$Z38,$AA$14:$AA38),$U38) -> 49.5 | AC38: =IFERROR($A39-LOOKUP($A39,$Z$14:$Z38),"") -> 25 | AD38: {=IF(B38<>"",80,_xludf.NA())} -> 80
A39: =+INT(B39) -> 46229 | B39: =+[1]Balance_Madden!A37 -> 46229 | C39: =+VLOOKUP(B39,[1]Balance_Madden!$A$12:$E$5000,2) -> 226.33 | D39: =+VLOOKUP(B39,[1]Balance_Gatún!$A$13:$E$5087,2) -> 84.887 | E39: =+VLOOKUP(B39,[1]Balance_Madden!$A$12:$E$5087,5)/35.32 -> 25.342044 | F39: =+VLOOKUP(B39,[1]Balance_Gatún!$A$13:$E$5087,5)/35.32 -> 30.384994 | G39: =+VLOOKUP(B39,[1]Balance_Madden!$A$12:$K$5087,9)/111 -> 2.6666667 | H39: =+VLOOKUP(B39,[1]Balance_Gatún!$A$13:$U$5087,21)/186 -> 0 | I39: =+(VLOOKUP(B39,[1]Balance_Madden!$A$12:$K$5087,10)/35.32)+VLOOKUP(B39,[1]Balance_Madden!$A$12:$K$5087,11)/35.32 -> 0 | J39: =+VLOOKUP(B39,[1]Balance_Gatún!$A$13:$AD$5087,23)/35.32+ VLOOKUP(B39,[1]Balance_Gatún!$A$13:$AD$5087,17)/35.32 -> 0 | K39: =+VLOOKUP(B39,[1]Balance_Gatún!$A$13:$AC$5087,10) -> 24 | L39: =+VLOOKUP(B39,[1]Balance_Gatún!$A$13:$AC$5087,11) -> XFILL_PMG50% | M39: =+VLOOKUP(B39,[1]Balance_Gatún!$A$13:$AC$5087,12) -> 10 | N39: =+VLOOKUP(B39,[1]Balance_Gatún!$A$13:$AC$5087,13) -> TA+CCL50% | O39: =+VLOOKUP(B39,[1]Balance_Gatún!$A$13:$AC$5087,14)/408.7 -> 7.2601828 | P39: =+VLOOKUP(B39,[1]Balance_Madden!$A$12:$V$5087,12)/35.32 -> 1.2619296 | Q39: =+VLOOKUP(B39,[1]Balance_Gatún!$A$13:$AD$5087,15)/35.32 -> 13.918192 | R39: =+VLOOKUP(B39,[1]Balance_Madden!$A$12:$V$5087,14)/35.32 -> 21.896131 | S39: =[1]Balance_Gatún!X38/35.32 -> 109.56932 | T39: 46.634578 | U39: 37.386412 | V39: =LOOKUP(D39,[1]Parámetros!$A$7:$A$24,[1]Parámetros!$B$7:$B$24) -> 49.5 | W39: =IF(V39<>V38,"Cambio Calado","") | X39: =IF(W39<>"",INT(A39),"") | Y39: =IF($W39="Cambio Calado",COUNTIF($W$14:W39,"Cambio Calado"),"") | Z39: =IF($W39="Cambio Calado",$X39,"") | AA39: =IF($W39="Cambio Calado",$V39,"") | AB39: =IFERROR(LOOKUP($A39,$Z$14:$Z39,$AA$14:$AA39),$U39) -> 49.5 | AC39: =IFERROR($A40-LOOKUP($A40,$Z$14:$Z39),"") -> 26 | AD39: {=IF(B39<>"",80,_xludf.NA())} -> 80
... A196: =+INT(B196) -> 46386 | B196: =+[1]Balance_Madden!A194 -> 46386 | C196: =+VLOOKUP(B196,[1]Balance_Madden!$A$12:$E$5000,2) -> 252.167 | D196: =+VLOOKUP(B196,[1]Balance_Gatún!$A$13:$E$5087,2) -> 83.596543 | E196: =+VLOOKUP(B196,[1]Balance_Madden!$A$12:$E$5087,5)/35.32 -> 21.016959 | F196: =+VLOOKUP(B196,[1]Balance_Gatún!$A$13:$E$5087,5)/35.32 -> 51.884456 | G196: =+VLOOKUP(B196,[1]Balance_Madden!$A$12:$K$5087,9)/111 -> 2.7027027 | H196: =+VLOOKUP(B196,[1]Balance_Gatún!$A$13:$U$5087,21)/186 -> 0 | I196: =+(VLOOKUP(B196,[1]Balance_Madden!$A$12:$K$5087,10)/35.32)+VLOOKUP(B196,[1]Balance_Madden!$A$12:$K$5087,11)/35.32 -> 8.4286786 | J196: =+VLOOKUP(B196,[1]Balance_Gatún!$A$13:$AD$5087,23)/35.32+ VLOOKUP(B196,[1]Balance_Gatún!$A$13:$AD$5087,17)/35.32 -> 0 | K196: =+VLOOKUP(B196,[1]Balance_Gatún!$A$13:$AC$5087,10) -> 18 | L196: =+VLOOKUP(B196,[1]Balance_Gatún!$A$13:$AC$5087,11) -> XFILL_PMG100% | M196: =+VLOOKUP(B196,[1]Balance_Gatún!$A$13:$AC$5087,12) -> 10 | N196: =+VLOOKUP(B196,[1]Balance_Gatún!$A$13:$AC$5087,13) -> TA+CCL100% | O196: =+VLOOKUP(B196,[1]Balance_Gatún!$A$13:$AC$5087,14)/408.7 -> 5.2051767 | P196: =+VLOOKUP(B196,[1]Balance_Madden!$A$12:$V$5087,12)/35.32 -> 0.9805878 | Q196: =+VLOOKUP(B196,[1]Balance_Gatún!$A$13:$AD$5087,15)/35.32 -> 7.5802281 | R196: =+VLOOKUP(B196,[1]Balance_Madden!$A$12:$V$5087,14)/35.32 -> 30.156718 | S196: =[1]Balance_Gatún!X195/35.32 -> 79.452163 | T196: 66.694991 | U196: 79.273982 | V196: =LOOKUP(D196,[1]Parámetros!$A$7:$A$24,[1]Parámetros!$B$7:$B$24) -> 48.5 | W196: =IF(V196<>V195,"Cambio Calado","") | X196: =IF(W196<>"",INT(A196),"") | Y196: =IF($W196="Cambio Calado",COUNTIF($W$14:W196,"Cambio Calado"),"") | Z196: =IF($W196="Cambio Calado",$X196,"") | AA196: =IF($W196="Cambio Calado",$V196,"") | AB196: =IFERROR(LOOKUP($A196,$Z$14:$Z196,$AA$14:$AA196),$U196) -> 48.5 | AC196: =IFERROR($A197-LOOKUP($A197,$Z$14:$Z196),"") -> 19 | AD196: {=IF(B196<>"",80,_xludf.NA())} -> 80
A197: =+INT(B197) -> 46387 | B197: =+[1]Balance_Madden!A195 -> 46387 | C197: =+VLOOKUP(B197,[1]Balance_Madden!$A$12:$E$5000,2) -> 252.113 | D197: =+VLOOKUP(B197,[1]Balance_Gatún!$A$13:$E$5087,2) -> 83.589284 | E197: =+VLOOKUP(B197,[1]Balance_Madden!$A$12:$E$5087,5)/35.32 -> 25.406625 | F197: =+VLOOKUP(B197,[1]Balance_Gatún!$A$13:$E$5087,5)/35.32 -> 19.410957 | G197: =+VLOOKUP(B197,[1]Balance_Madden!$A$12:$K$5087,9)/111 -> 0 | H197: =+VLOOKUP(B197,[1]Balance_Gatún!$A$13:$U$5087,21)/186 -> 0 | I197: =+(VLOOKUP(B197,[1]Balance_Madden!$A$12:$K$5087,10)/35.32)+VLOOKUP(B197,[1]Balance_Madden!$A$12:$K$5087,11)/35.32 -> 6.3720076 | J197: =+VLOOKUP(B197,[1]Balance_Gatún!$A$13:$AD$5087,23)/35.32+ VLOOKUP(B197,[1]Balance_Gatún!$A$13:$AD$5087,17)/35.32 -> 0 | K197: =+VLOOKUP(B197,[1]Balance_Gatún!$A$13:$AC$5087,10) -> 18 | L197: =+VLOOKUP(B197,[1]Balance_Gatún!$A$13:$AC$5087,11) -> XFILL_PMG100% | M197: =+VLOOKUP(B197,[1]Balance_Gatún!$A$13:$AC$5087,12) -> 10 | N197: =+VLOOKUP(B197,[1]Balance_Gatún!$A$13:$AC$5087,13) -> TA+CCL100% | O197: =+VLOOKUP(B197,[1]Balance_Gatún!$A$13:$AC$5087,14)/408.7 -> 5.2040433 | P197: =+VLOOKUP(B197,[1]Balance_Madden!$A$12:$V$5087,12)/35.32 -> 1.5801257 | Q197: =+VLOOKUP(B197,[1]Balance_Gatún!$A$13:$AD$5087,15)/35.32 -> 12.221566 | R197: =+VLOOKUP(B197,[1]Balance_Madden!$A$12:$V$5087,14)/35.32 -> 20.205814 | S197: =[1]Balance_Gatún!X196/35.32 -> 84.080384 | T197: 20.997375 | U197: 87.882793 | V197: =LOOKUP(D197,[1]Parámetros!$A$7:$A$24,[1]Parámetros!$B$7:$B$24) -> 48.5 | W197: =IF(V197<>V196,"Cambio Calado","") | X197: =IF(W197<>"",INT(A197),"") | Y197: =IF($W197="Cambio Calado",COUNTIF($W$14:W197,"Cambio Calado"),"") | Z197: =IF($W197="Cambio Calado",$X197,"") | AA197: =IF($W197="Cambio Calado",$V197,"") | AB197: =IFERROR(LOOKUP($A197,$Z$14:$Z197,$AA$14:$AA197),$U197) -> 48.5 | AD197: {=IF(B197<>"",80,_xludf.NA())} -> 80
A198: =+INT(B198) -> 0
A199: =+INT(B199) -> 0
A200: =+INT(B200) -> 0
A201: =+INT(B201) -> 0
...

Sheet Sheet1
